Workbook

Sheet June Master Duty Overview
A1: Duty Personnel Duty | B1: Total Points | C1: Duty Points | D1: Reserve Points | E1: Reserve Points 2 | F1: SATURDAY (AM) | G1: SATURDAY (PM) | H1: SUNDAY (AM) | I1: SUNDAY (PM) | J1: MONDAY | K1: TUESDAY | L1: WEDNESDAY | M1: THURSDAY | N1: FRIDAY | O1: SATURDAY (AM) | P1: SATURDAY (PM) | Q1: SUNDAY (AM) | R1: SUNDAY (PM) | S1: MONDAY | T1: TUESDAY | U1: WEDNESDAY | V1: THURSDAY | W1: FRIDAY | X1: SATURDAY (AM) | Y1: SATURDAY (PM) | Z1: SUNDAY (AM) | AA1: SUNDAY (PM) | AB1: MONDAY (AM) | AC1: MONDAY (PM) | AD1: TUESDAY | AE1: WEDNESDAY | AF1: THURSDAY | AG1: FRIDAY | AH1: SATURDAY (AM) | AI1: SATURDAY (PM) | AJ1: SUNDAY (AM) | AK1: SUNDAY (PM) | AL1: MONDAY | AM1: TUESDAY | AN1: WEDNESDAY | AO1: THURSDAY | AP1: FRIDAY | AQ1: SATURDAY (AM) | AR1: SATURDAY (PM) | AS1: SUNDAY (AM) | AT1: SUNDAY (PM)
F2: 1-6-24 (AM) | G2: 1-6-24 (PM) | H2: 2-6-24 (AM) | I2: 2-6-24 (PM) | J2: 45446 | K2: 45447 | L2: 45448 | M2: 45449 | N2: 45450 | O2: 8-6-24 (AM) | P2: 8-6-24 (PM) | Q2: 9-6-24 (AM) | R2: 9-6-24 (PM) | S2: 45453 | T2: 45454 | U2: 45455 | V2: 45456 | W2: 45457 | X2: 15-6-24 (AM) | Y2: 15-6-24 (PM) | Z2: 16-6-24 (AM) | AA2: 16-6-24 (PM) | AB2: 17-6-24 (AM) | AC2: 17-6-24 (PM) | AD2: 45461 | AE2: 45462 | AF2: 45463 | AG2: 45464 | AH2: 22-6-24 (AM) | AI2: 22-6-24 (PM) | AJ2: 23-6-24 (AM) | AK2: 23-6-24 (PM) | AL2: 45467 | AM2: 45468 | AN2: 45469 | AO2: 45470 | AP2: 45471 | AQ2: 29-6-24 (AM) | AR2: 29-6-24 (PM) | AS2: 30-6-24 (AM) | AT2: 30-6-24 (PM)
A3: PTE EZRA | B3: =SUM(C3:D3) -> 4 | C3: =SUM(F3:AW3) -> 2 | D3: {=SUM(IF(F3:AW3="R",1,0))} -> 2 | E3: {=SUM(IF(F3:AW3="R2",1,0))} -> 2 | M3: r | N3: 1 | O3: r | P3: 1 | AE3: r2 | AF3: r2
A4: PTE LI HUI | B4: =SUM(C4:D4) -> 3 | C4: =SUM(F4:AW4) -> 2 | D4: {=SUM(IF(F4:AW4="R",1,0))} -> 1 | E4: {=SUM(IF(F4:AW4="R2",1,0))} -> 1 | F4: 1 | X4: r | AG4: r2 | AT4: 1
A5: PTE ERNEST | B5: =SUM(C5:D5) -> 3 | C5: =SUM(F5:AW5) -> 1 | D5: {=SUM(IF(F5:AW5="R",1,0))} -> 2 | E5: {=SUM(IF(F5:AW5="R2",1,0))} -> 2 | F5: r | R5: r | S5: 1 | T5: r2 | AA5: r2
A6: PTE FIRMAN | B6: =SUM(C6:D6) -> 3 | C6: =SUM(F6:AW6) -> 1 | D6: {=SUM(IF(F6:AW6="R",1,0))} -> 2 | E6: {=SUM(IF(F6:AW6="R2",1,0))} -> 1 | R6: r2 | S6: r | T6: r | AA6: 1
A7: PTE AFIF | B7: =SUM(C7:D7) -> 2 | C7: =SUM(F7:AW7) -> 1 | D7: {=SUM(IF(F7:AW7="R",1,0))} -> 1 | E7: {=SUM(IF(F7:AW7="R2",1,0))} -> 1 | S7: r2 | T7: 1 | AG7: r
A8: PTE ADAM | B8: =SUM(C8:D8) -> 2 | C8: =SUM(F8:AW8) -> 1 | D8: {=SUM(IF(F8:AW8="R",1,0))} -> 1 | E8: {=SUM(IF(F8:AW8="R2",1,0))} -> 2 | K8: r2 | AA8: r | AC8: 1 | AS8: r2
A9: PTE REUVEN | B9: =SUM(C9:D9) -> 2 | C9: =SUM(F9:AW9) -> 1 | D9: {=SUM(IF(F9:AW9="R",1,0))} -> 1 | E9: {=SUM(IF(F9:AW9="R2",1,0))} -> 1 | K9: r | AC9: r2 | AS9: 1
A10: LCP AMIRUL | B10: =SUM(C10:D10) -> 4 | C10: =SUM(F10:AW10) -> 1 | D10: {=SUM(IF(F10:AW10="R",1,0))} -> 3 | E10: {=SUM(IF(F10:AW10="R2",1,0))} -> 1 | K10: 1 | Q10: r2 | Z10: r | AC10: r | AS10: r
A11: PTE YU CHEN | C11: =SUM(F11:AW11) -> 0 | D11: {=SUM(IF(F11:AW11="R",1,0))} -> 0 | E11: {=SUM(IF(F11:AW11="R2",1,0))} -> 0
A12: PTE HOI REI | B12: =SUM(C12:D12) -> 0 | C12: =SUM(F12:AW12) -> 0 | D12: {=SUM(IF(F12:AW12="R",1,0))} -> 0 | E12: {=SUM(IF(F12:AW12="R2",1,0))} -> 0
A13: PTE DANIEL | B13: =SUM(C13:D13) -> 5 | C13: =SUM(F13:AW13) -> 2 | D13: {=SUM(IF(F13:AW13="R",1,0))} -> 3 | E13: {=SUM(IF(F13:AW13="R2",1,0))} -> 3 | L13: r | U13: r | W13: 1 | AH13: r2 | AI13: r2 | AK13: r | AN13: r2 | AP13: 1
B14: =SUM(C14:D14) -> 0 | C14: =SUM(F14:AW14) -> 0 | D14: {=SUM(IF(F14:AW14="R",1,0))} -> 0 | E14: {=SUM(IF(F14:AW14="R2",1,0))} -> 0
A15: PTE ANGELO | B15: =SUM(C15:D15) -> 4 | C15: =SUM(F15:AW15) -> 2 | D15: {=SUM(IF(F15:AW15="R",1,0))} -> 2 | E15: {=SUM(IF(F15:AW15="R2",1,0))} -> 3 | L15: 1 | O15: r2 | U15: r2 | W15: r | AI15: 1 | AK15: r2 | AN15: r
A16: PTE MATTHEW | B16: =SUM(C16:D16) -> 3 | C16: =SUM(F16:AW16) -> 2 | D16: {=SUM(IF(F16:AW16="R",1,0))} -> 1 | E16: {=SUM(IF(F16:AW16="R2",1,0))} -> 1 | L16: r2 | AK16: 1 | AN16: 1 | AP16: r
A17: REC ETHAN | B17: =SUM(C17:D17) -> 3 | C17: =SUM(F17:AW17) -> 2 | D17: {=SUM(IF(F17:AW17="R",1,0))} -> 1 | E17: {=SUM(IF(F17:AW17="R2",1,0))} -> 2 | U17: 1 | W17: r2 | AG17: 1 | AI17: r | AP17: r2
C18: =SUM(F18:AW18) -> 0 | D18: {=SUM(IF(F18:AW18="R",1,0))} -> 0 | E18: {=SUM(IF(F18:AW18="R2",1,0))} -> 0
A19: REC AKMAL | B19: =SUM(C19:D19) -> 0 | C19: =SUM(F19:AW19) -> 0 | D19: {=SUM(IF(F19:AW19="R",1,0))} -> 0 | E19: {=SUM(IF(F19:AW19="R2",1,0))} -> 0
A20: REC RUI FENG | B20: =SUM(C20:D20) -> 5 | C20: =SUM(F20:AW20) -> 3 | D20: {=SUM(IF(F20:AW20="R",1,0))} -> 2 | E20: {=SUM(IF(F20:AW20="R2",1,0))} -> 1 | F20: r2 | O20: 1 | Q20: r | Z20: 1 | AH20: 1 | AJ20: r
B21: =SUM(C21:D21) -> 0 | C21: =SUM(F21:AW21) -> 0 | D21: {=SUM(IF(F21:AW21="R",1,0))} -> 0 | E21: {=SUM(IF(F21:AW21="R2",1,0))} -> 0
A22: PTE JASPER | B22: =SUM(C22:D22) -> 0 | C22: =SUM(F22:AW22) -> 0 | D22: {=SUM(IF(F22:AW22="R",1,0))} -> 0 | E22: {=SUM(IF(F22:AW22="R2",1,0))} -> 0
A23: PTE RIFQI | B23: =SUM(C23:D23) -> 3 | C23: =SUM(F23:AW23) -> 2 | D23: {=SUM(IF(F23:AW23="R",1,0))} -> 1 | E23: {=SUM(IF(F23:AW23="R2",1,0))} -> 1 | Z23: r2 | AH23: r | AJ23: 1 | AQ23: 1
A24: PTE HAQIMI | B24: =SUM(C24:D24) -> 3 | C24: =SUM(F24:AW24) -> 1 | D24: {=SUM(IF(F24:AW24="R",1,0))} -> 2 | E24: {=SUM(IF(F24:AW24="R2",1,0))} -> 3 | G24: r | J24: r2 | V24: r | Y24: r2 | AD24: 1 | AR24: r2
A25: PTE DARREN | B25: =SUM(C25:D25) -> 6 | C25: =SUM(F25:AW25) -> 5 | D25: {=SUM(IF(F25:AW25="R",1,0))} -> 1 | E25: {=SUM(IF(F25:AW25="R2",1,0))} -> 3 | G25: 1 | H25: r | I25: r2 | Q25: 1 | R25: 1 | AB25: 1 | AL25: r2 | AM25: r2 | AO25: 1
A26: PTE SAMEER | B26: =SUM(C26:D26) -> 6 | C26: =SUM(F26:AW26) -> 5 | D26: {=SUM(IF(F26:AW26="R",1,0))} -> 1 | E26: {=SUM(IF(F26:AW26="R2",1,0))} -> 2 | H26: 1 | I26: 1 | X26: 1 | Y26: 1 | AL26: r | AM26: 1 | AO26: r2 | AT26: r2
A27: PTE XIAO YU | B27: =SUM(C27:D27) -> 6 | C27: =SUM(F27:AW27) -> 1 | D27: {=SUM(IF(F27:AW27="R",1,0))} -> 5 | E27: {=SUM(IF(F27:AW27="R2",1,0))} -> 2 | G27: r2 | H27: R2 | I27: r | AB27: R | AL27: 1 | AM27: r | AO27: r | AT27: r
A28: PTE DAVID | B28: =SUM(C28:D28) -> 4 | C28: =SUM(F28:AW28) -> 2 | D28: {=SUM(IF(F28:AW28="R",1,0))} -> 2 | E28: {=SUM(IF(F28:AW28="R2",1,0))} -> 4 | J28: 1 | M28: r2 | X28: r2 | Y28: r | AB28: r2 | AD28: r | AQ28: r2 | AR28: 1
A29: CPL YUSUF | C29: =SUM(F29:AW29) -> 1 | D29: {=SUM(IF(F29:AW29="R",1,0))} -> 4 | E29: {=SUM(IF(F29:AW29="R2",1,0))} -> 3 | J29: r | M29: 1 | N29: r2 | P29: r | AD29: r2 | AJ29: r2 | AQ29: r | AR29: r
A30: REC HAO QIAN | B30: =SUM(C30:D30) -> 3 | C30: =SUM(F30:AW30) -> 1 | D30: {=SUM(IF(F30:AW30="R",1,0))} -> 2 | E30: {=SUM(IF(F30:AW30="R2",1,0))} -> 1 | N30: r | V30: r2 | AE30: 1 | AF30: r
A31: PTE JIREH | B31: =SUM(C31:D31) -> 3 | C31: =SUM(F31:AW31) -> 2 | D31: {=SUM(IF(F31:AW31="R",1,0))} -> 1 | E31: {=SUM(IF(F31:AW31="R2",1,0))} -> 1 | P31: r2 | V31: 1 | AE31: r | AF31: 1
A32: Total | B32: =SUM(B4:B21) -> 39 | C32: =SUM(F32:AW32) -> 41 | F32: =SUM(F3:F31) -> 1 | G32: =SUM(G3:G31) -> 1 | H32: =SUM(H3:H31) -> 1 | I32: =SUM(I3:I31) -> 1 | J32: =SUM(J3:J31) -> 1 | K32: =SUM(K3:K31) -> 1 | L32: =SUM(L3:L31) -> 1 | M32: =SUM(M3:M31) -> 1 | ... AT32: =SUM(AT3:AT31) -> 1
A33: Reserve 1 | B33: =SUM(F33:AW33) -> 41 | C33: =SUM(F33:AW33) -> 41 | F33: {=SUM(IF(F3:F31="R",1,0))} -> 1 | G33: {=SUM(IF(G3:G31="R",1,0))} -> 1 | H33: {=SUM(IF(H3:H31="R",1,0))} -> 1 | I33: {=SUM(IF(I3:I31="R",1,0))} -> 1 | J33: {=SUM(IF(J3:J31="R",1,0))} -> 1 | K33: {=SUM(IF(K3:K31="R",1,0))} -> 1 | L33: {=SUM(IF(L3:L31="R",1,0))} -> 1 | M33: {=SUM(IF(M3:M31="R",1,0))} -> 1 | ... AT33: {=SUM(IF(AT3:AT31="R",1,0))} -> 1
A34: Reserve 2 | B34: =SUM(F34:AW34) -> 41 | C34: =SUM(F34:AW34) -> 41 | F34: {=SUM(IF(F3:F31="R2",1,0))} -> 1 | G34: {=SUM(IF(G3:G31="R2",1,0))} -> 1 | H34: {=SUM(IF(H3:H31="R2",1,0))} -> 1 | I34: {=SUM(IF(I3:I31="R2",1,0))} -> 1 | J34: {=SUM(IF(J3:J31="R2",1,0))} -> 1 | K34: {=SUM(IF(K3:K31="R2",1,0))} -> 1 | L34: {=SUM(IF(L3:L31="R2",1,0))} -> 1 | M34: {=SUM(IF(M3:M31="R2",1,0))} -> 1 | ... AT34: {=SUM(IF(AT3:AT31="R2",1,0))} -> 1
E35: Duty Clerk | F35: =IFERROR(INDEX($A$3:$A$31, MATCH(1, INDEX($F$3:$AW$31, 0, MATCH(F2, $F$2:$AW$2, 0)), 0)), INDEX($A$3:$A$31, MATCH(1, INDEX($F$3:$AW$31, 0, MATCH(F2&" AM", $F$2:$AW$2, 0)), 0))) -> PTE LI HUI | G35: =IFERROR(INDEX($A$3:$A$31, MATCH(1, INDEX($F$3:$AW$31, 0, MATCH(G2, $F$2:$AW$2, 0)), 0)), INDEX($A$3:$A$31, MATCH(1, INDEX($F$3:$AW$31, 0, MATCH(G2&" AM", $F$2:$AW$2, 0)), 0))) -> PTE DARREN | H35: =IFERROR(INDEX($A$3:$A$31, MATCH(1, INDEX($F$3:$AW$31, 0, MATCH(H2, $F$2:$AW$2, 0)), 0)), INDEX($A$3:$A$31, MATCH(1, INDEX($F$3:$AW$31, 0, MATCH(H2&" AM", $F$2:$AW$2, 0)), 0))) -> PTE SAMEER | I35: =IFERROR(INDEX($A$3:$A$31, MATCH(1, INDEX($F$3:$AW$31, 0, MATCH(I2, $F$2:$AW$2, 0)), 0)), INDEX($A$3:$A$31, MATCH(1, INDEX($F$3:$AW$31, 0, MATCH(I2&" AM", $F$2:$AW$2, 0)), 0))) -> PTE SAMEER | J35: =IFERROR(INDEX($A$3:$A$31, MATCH(1, INDEX($F$3:$AW$31, 0, MATCH(J2, $F$2:$AW$2, 0)), 0)), INDEX($A$3:$A$31, MATCH(1, INDEX($F$3:$AW$31, 0, MATCH(J2&" AM", $F$2:$AW$2, 0)), 0))) -> PTE DAVID | K35: =IFERROR(INDEX($A$3:$A$31, MATCH(1, INDEX($F$3:$AW$31, 0, MATCH(K2, $F$2:$AW$2, 0)), 0)), INDEX($A$3:$A$31, MATCH(1, INDEX($F$3:$AW$31, 0, MATCH(K2&" AM", $F$2:$AW$2, 0)), 0))) -> LCP AMIRUL | L35: =IFERROR(INDEX($A$3:$A$31, MATCH(1, INDEX($F$3:$AW$31, 0, MATCH(L2, $F$2:$AW$2, 0)), 0)), INDEX($A$3:$A$31, MATCH(1, INDEX($F$3:$AW$31, 0, MATCH(L2&" AM", $F$2:$AW$2, 0)), 0))) -> PTE ANGELO | M35: =IFERROR(INDEX($A$3:$A$31, MATCH(1, INDEX($F$3:$AW$31, 0, MATCH(M2, $F$2:$AW$2, 0)), 0)), INDEX($A$3:$A$31, MATCH(1, INDEX($F$3:$AW$31, 0, MATCH(M2&" AM", $F$2:$AW$2, 0)), 0))) -> CPL YUSUF | ... AT35: =IFERROR(INDEX($A$3:$A$31, MATCH(1, INDEX($F$3:$AW$31, 0, MATCH(AT2, $F$2:$AW$2, 0)), 0)), INDEX($A$3:$A$31, MATCH(1, INDEX($F$3:$AW$31, 0, MATCH(AT2&" AM", $F$2:$AW$2, 0)), 0))) -> PTE LI HUI
E36: Reserve | F36: =INDEX($A$3:$A$31, MATCH("R", INDEX($F$3:$AW$31, 0, MATCH(F2, $F$2:$AW$2, 0)), 0)) -> PTE ERNEST | G36: =INDEX($A$3:$A$31, MATCH("R", INDEX($F$3:$AW$31, 0, MATCH(G2, $F$2:$AW$2, 0)), 0)) -> PTE HAQIMI | H36: =INDEX($A$3:$A$31, MATCH("R", INDEX($F$3:$AW$31, 0, MATCH(H2, $F$2:$AW$2, 0)), 0)) -> PTE DARREN | I36: =INDEX($A$3:$A$31, MATCH("R", INDEX($F$3:$AW$31, 0, MATCH(I2, $F$2:$AW$2, 0)), 0)) -> PTE XIAO YU | J36: =INDEX($A$3:$A$31, MATCH("R", INDEX($F$3:$AW$31, 0, MATCH(J2, $F$2:$AW$2, 0)), 0)) -> CPL YUSUF | K36: =INDEX($A$3:$A$31, MATCH("R", INDEX($F$3:$AW$31, 0, MATCH(K2, $F$2:$AW$2, 0)), 0)) -> PTE REUVEN | L36: =INDEX($A$3:$A$31, MATCH("R", INDEX($F$3:$AW$31, 0, MATCH(L2, $F$2:$AW$2, 0)), 0)) -> PTE DANIEL | M36: =INDEX($A$3:$A$31, MATCH("R", INDEX($F$3:$AW$31, 0, MATCH(M2, $F$2:$AW$2, 0)), 0)) -> PTE EZRA | ... AT36: =INDEX($A$3:$A$31, MATCH("R", INDEX($F$3:$AW$31, 0, MATCH(AT2, $F$2:$AW$2, 0)), 0)) -> PTE XIAO YU
E37: Reserve 2 | F37: =INDEX($A$3:$A$31, MATCH("R2", INDEX($F$3:$AW$31, 0, MATCH(F2, $F$2:$AW$2, 0)), 0)) -> REC RUI FENG | G37: =INDEX($A$3:$A$31, MATCH("R2", INDEX($F$3:$AW$31, 0, MATCH(G2, $F$2:$AW$2, 0)), 0)) -> PTE XIAO YU | H37: =INDEX($A$3:$A$31, MATCH("R2", INDEX($F$3:$AW$31, 0, MATCH(H2, $F$2:$AW$2, 0)), 0)) -> PTE XIAO YU | I37: =INDEX($A$3:$A$31, MATCH("R2", INDEX($F$3:$AW$31, 0, MATCH(I2, $F$2:$AW$2, 0)), 0)) -> PTE DARREN | J37: =INDEX($A$3:$A$31, MATCH("R2", INDEX($F$3:$AW$31, 0, MATCH(J2, $F$2:$AW$2, 0)), 0)) -> PTE HAQIMI | K37: =INDEX($A$3:$A$31, MATCH("R2", INDEX($F$3:$AW$31, 0, MATCH(K2, $F$2:$AW$2, 0)), 0)) -> PTE ADAM | L37: =INDEX($A$3:$A$31, MATCH("R2", INDEX($F$3:$AW$31, 0, MATCH(L2, $F$2:$AW$2, 0)), 0)) -> PTE MATTHEW | M37: =INDEX($A$3:$A$31, MATCH("R2", INDEX($F$3:$AW$31, 0, MATCH(M2, $F$2:$AW$2, 0)), 0)) -> PTE DAVID | ... AT37: =INDEX($A$3:$A$31, MATCH("R2", INDEX($F$3:$AW$31, 0, MATCH(AT2, $F$2:$AW$2, 0)), 0)) -> PTE SAMEER

Sheet July Master Duty Overview
A1: Duty Personnel Duty | B1: Total Points | C1: Duty Points | D1: Reserve Points | E1: Reserve Points 2 | F1: MONDAY | G1: TUESDAY | H1: WEDNESDAY | I1: THURSDAY | J1: FRIDAY | K1: SATURDAY (AM) | L1: SATURDAY (PM) | M1: SUNDAY (AM) | N1: SUNDAY (PM) | O1: MONDAY | P1: TUESDAY | Q1: WEDNESDAY | R1: THURSDAY | S1: FRIDAY | T1: SATURDAY (AM) | U1: SATURDAY (PM) | V1: SUNDAY (AM) | W1: SUNDAY (PM) | X1: MONDAY | Y1: TUESDAY | Z1: WEDNESDAY | AA1: THURSDAY | AB1: FRIDAY | AC1: SATURDAY (AM) | AD1: SATURDAY (PM) | AE1: SUNDAY (AM) | AF1: SUNDAY (PM) | AG1: MONDAY | AH1: TUESDAY | AI1: WEDNESDAY | AJ1: THURSDAY | AK1: FRIDAY | AL1: SATURDAY (AM) | AM1: SATURDAY (PM) | AN1: SUNDAY (AM) | AO1: SUNDAY (PM) | AP1: MONDAY | AQ1: TUESDAY | AR1: WEDNESDAY
F2: 45474 | G2: 45475 | H2: 45476 | I2: 45477 | J2: 45478 | K2: 6-7-24 (AM) | L2: 6-7-24 (PM) | M2: 7-7-24 (AM) | N2: 7-7-24 (PM) | O2: 45481 | P2: 45482 | Q2: 45483 | R2: 45484 | S2: 45485 | T2: 13-7-24 (AM) | U2: 13-7-24 (PM) | V2: 14-7-24 (AM) | W2: 14-7-24 (PM) | X2: 45488 | Y2: 45489 | Z2: 45490 | AA2: 45491 | AB2: 45492 | AC2: 20-7-24 (AM) | AD2: 20-7-24 (PM) | AE2: 21-7-24 (AM) | AF2: 21-7-24 (PM) | AG2: 45495 | AH2: 45496 | AI2: 45497 | AJ2: 45498 | AK2: 45499 | AL2: 27-7-24 (AM) | AM2: 27-7-24 (PM) | AN2: 28-7-24 (AM) | AO2: 28-7-24 (PM) | AP2: 45502 | AQ2: 45503 | AR2: 45504
A3: PTE EZRA | B3: =SUM(C3:D3) -> 3 | C3: =SUM(F3:AR3) -> 2 | D3: {=SUM(IF(F3:AR3="R",1,0))} -> 1 | E3: {=SUM(IF(F3:AR3="R2",1,0))} -> 2 | J3: r2 | M3: 1 | P3: r2 | AM3: 1 | AR3: r
A4: PTE LI HUI | B4: =SUM(C4:D4) -> 3 | C4: =SUM(F4:AR4) -> 2 | D4: {=SUM(IF(F4:AR4="R",1,0))} -> 1 | E4: {=SUM(IF(F4:AR4="R2",1,0))} -> 2 | K4: r | L4: 1 | T4: 1 | AC4: r2 | AF4: r2
A5: PTE ERNEST | B5: =SUM(C5:D5) -> 4 | C5: =SUM(F5:AR5) -> 2 | D5: {=SUM(IF(F5:AR5="R",1,0))} -> 2 | E5: {=SUM(IF(F5:AR5="R2",1,0))} -> 2 | H5: 1 | I5: r | T5: r | V5: r2 | AD5: r2 | AI5: 1
A6: PTE FIRMAN | B6: =SUM(C6:D6) -> 3 | C6: =SUM(F6:AR6) -> 2 | D6: {=SUM(IF(F6:AR6="R",1,0))} -> 1 | E6: {=SUM(IF(F6:AR6="R2",1,0))} -> 2 | L6: r2 | T6: r2 | AD6: 1 | AO6: 1 | AQ6: r
A7: PTE AFIF | B7: =SUM(C7:D7) -> 4 | C7: =SUM(F7:AR7) -> 2 | D7: {=SUM(IF(F7:AR7="R",1,0))} -> 2 | E7: {=SUM(IF(F7:AR7="R2",1,0))} -> 1 | Y7: r | AC7: 1 | AI7: r2 | AL7: r | AQ7: 1
A8: PTE YORI | C8: =SUM(F8:AR8) -> 1 | D8: {=SUM(IF(F8:AR8="R",1,0))} -> 1 | E8: {=SUM(IF(F8:AR8="R2",1,0))} -> 1 | AC8: r | AE8: r2 | AN8: 1
A9: PTE ADAM | B9: =SUM(C9:D9) -> 4 | C9: =SUM(F9:AR9) -> 2 | D9: {=SUM(IF(F9:AR9="R",1,0))} -> 2 | E9: {=SUM(IF(F9:AR9="R2",1,0))} -> 2 | L9: r | R9: r2 | W9: 1 | Z9: r | AH9: 1 | AJ9: r2
A10: PTE REUVEN | B10: =SUM(C10:D10) -> 3 | C10: =SUM(F10:AR10) -> 2 | D10: {=SUM(IF(F10:AR10="R",1,0))} -> 1 | E10: {=SUM(IF(F10:AR10="R2",1,0))} -> 2 | G10: r2 | N10: 1 | U10: r2 | W10: r | AK10: 1
A11: LCP AMIRUL | B11: =SUM(C11:D11) -> 0 | C11: =SUM(F11:AR11) -> 0 | D11: {=SUM(IF(F11:AR11="R",1,0))} -> 0 | E11: {=SUM(IF(F11:AR11="R2",1,0))} -> 0
A12: PTE DANIEL | B12: =SUM(C12:D12) -> 4 | C12: =SUM(F12:AR12) -> 2 | D12: {=SUM(IF(F12:AR12="R",1,0))} -> 2 | E12: {=SUM(IF(F12:AR12="R2",1,0))} -> 2 | S12: 1 | Y12: r2 | AA12: r | AB12: 1 | AF12: r | AQ12: r2
B13: =SUM(C13:D13) -> 0 | C13: =SUM(F13:AR13) -> 0 | D13: {=SUM(IF(F13:AR13="R",1,0))} -> 0 | E13: {=SUM(IF(F13:AR13="R2",1,0))} -> 0
A14: PTE ANGELO | B14: =SUM(C14:D14) -> 3 | C14: =SUM(F14:AR14) -> 1 | D14: {=SUM(IF(F14:AR14="R",1,0))} -> 2 | E14: {=SUM(IF(F14:AR14="R2",1,0))} -> 2 | S14: r | Y14: 1 | AA14: r2 | AJ14: r | AP14: r2
A15: REC RUI FENG | B15: =SUM(C15:D15) -> 2 | C15: =SUM(F15:AR15) -> 1 | D15: {=SUM(IF(F15:AR15="R",1,0))} -> 1 | E15: {=SUM(IF(F15:AR15="R2",1,0))} -> 1 | AE15: r | AL15: 1 | AN15: r2
A16: PTE MATTHEW | B16: =SUM(C16:D16) -> 4 | C16: =SUM(F16:AR16) -> 2 | D16: {=SUM(IF(F16:AR16="R",1,0))} -> 2 | E16: {=SUM(IF(F16:AR16="R2",1,0))} -> 1 | O16: r | P16: 1 | S16: r2 | AA16: 1 | AH16: r
A17: REC ETHAN | B17: =SUM(C17:D17) -> 4 | C17: =SUM(F17:AR17) -> 2 | D17: {=SUM(IF(F17:AR17="R",1,0))} -> 2 | E17: {=SUM(IF(F17:AR17="R2",1,0))} -> 2 | H17: r2 | J17: r | N17: r2 | P17: r | U17: 1 | AJ17: 1
C18: =SUM(F18:AR18) -> 0 | D18: {=SUM(IF(F18:AR18="R",1,0))} -> 0 | E18: {=SUM(IF(F18:AR18="R2",1,0))} -> 0
B19: =SUM(C19:D19) -> 0 | C19: =SUM(F19:AR19) -> 0 | D19: {=SUM(IF(F19:AR19="R",1,0))} -> 0 | E19: {=SUM(IF(F19:AR19="R2",1,0))} -> 0
A20: PTE AMIN | C20: =SUM(F20:AR20) -> 2 | D20: {=SUM(IF(F20:AR20="R",1,0))} -> 2 | E20: {=SUM(IF(F20:AR20="R2",1,0))} -> 2 | G20: r | J20: 1 | Q20: 1 | U20: r | AG20: r2 | AH20: r2
A21: PTE JASPER | B21: =SUM(C21:D21) -> 0 | C21: =SUM(F21:AR21) -> 0 | D21: {=SUM(IF(F21:AR21="R",1,0))} -> 0 | E21: {=SUM(IF(F21:AR21="R2",1,0))} -> 0
A22: REC PARAM | C22: =SUM(F22:AR22) -> 1 | D22: {=SUM(IF(F22:AR22="R",1,0))} -> 2 | E22: {=SUM(IF(F22:AR22="R2",1,0))} -> 1 | M22: r | V22: 1 | AL22: r2 | AN22: r
A23: PTE RIFQI | B23: =SUM(C23:D23) -> 2 | C23: =SUM(F23:AR23) -> 1 | D23: {=SUM(IF(F23:AR23="R",1,0))} -> 1 | E23: {=SUM(IF(F23:AR23="R2",1,0))} -> 1 | K23: 1 | M23: r2 | V23: r
A24: PTE HAQIMI | B24: =SUM(C24:D24) -> 3 | C24: =SUM(F24:AR24) -> 1 | D24: {=SUM(IF(F24:AR24="R",1,0))} -> 2 | E24: {=SUM(IF(F24:AR24="R2",1,0))} -> 2 | I24: 1 | K24: r2 | Q24: r | AI24: r | AK24: r2
A25: PTE DARREN | B25: =SUM(C25:D25) -> 4 | C25: =SUM(F25:AR25) -> 2 | D25: {=SUM(IF(F25:AR25="R",1,0))} -> 2 | E25: {=SUM(IF(F25:AR25="R2",1,0))} -> 2 | F25: 1 | H25: r | AB25: r | AE25: 1 | AO25: r2 | AR25: r2
A26: PTE SAMEER | B26: =SUM(C26:D26) -> 0 | C26: =SUM(F26:AR26) -> 0 | D26: {=SUM(IF(F26:AR26="R",1,0))} -> 0 | E26: {=SUM(IF(F26:AR26="R2",1,0))} -> 0
A27: PTE XIAO YU | B27: =SUM(C27:D27) -> 4 | C27: =SUM(F27:AR27) -> 2 | D27: {=SUM(IF(F27:AR27="R",1,0))} -> 2 | E27: {=SUM(IF(F27:AR27="R2",1,0))} -> 2 | F27: r | X27: r2 | Z27: 1 | AB27: r2 | AF27: 1 | AP27: r
A28: PTE DAVID | B28: =SUM(C28:D28) -> 0 | C28: =SUM(F28:AR28) -> 0 | D28: {=SUM(IF(F28:AR28="R",1,0))} -> 0 | E28: {=SUM(IF(F28:AR28="R2",1,0))} -> 0
A29: CPL YUSUF | C29: =SUM(F29:AR29) -> 2 | D29: {=SUM(IF(F29:AR29="R",1,0))} -> 2 | E29: {=SUM(IF(F29:AR29="R2",1,0))} -> 1 | F29: r2 | N29: r | R29: 1 | X29: r | AP29: 1
A30: PTE HOI REI | C30: =SUM(F30:AR30) -> 2 | D30: {=SUM(IF(F30:AR30="R",1,0))} -> 2 | E30: {=SUM(IF(F30:AR30="R2",1,0))} -> 2 | R30: r | X30: 1 | Z30: r2 | AM30: r2 | AO30: r | AR30: 1
A31: REC HAO QIAN | B31: =SUM(C31:D31) -> 4 | C31: =SUM(F31:AR31) -> 2 | D31: {=SUM(IF(F31:AR31="R",1,0))} -> 2 | E31: {=SUM(IF(F31:AR31="R2",1,0))} -> 2 | O31: 1 | Q31: r2 | W31: r2 | AG31: 1 | AK31: r | AM31: r
A32: PTE JIREH | B32: =SUM(C32:D32) -> 3 | C32: =SUM(F32:AR32) -> 1 | D32: {=SUM(IF(F32:AR32="R",1,0))} -> 2 | E32: {=SUM(IF(F32:AR32="R2",1,0))} -> 2 | G32: 1 | I32: r2 | O32: r2 | AD32: r | AG32: r
A33: Total | B33: =SUM(B4:B19) -> 38 | C33: =SUM(F33:AR33) -> 39 | F33: =SUM(F3:F32) -> 1 | G33: =SUM(G3:G32) -> 1 | H33: =SUM(H3:H32) -> 1 | I33: =SUM(I3:I32) -> 1 | J33: =SUM(J3:J32) -> 1 | K33: =SUM(K3:K32) -> 1 | L33: =SUM(L3:L32) -> 1 | M33: =SUM(M3:M32) -> 1 | ... AR33: =SUM(AR3:AR32) -> 1
A34: Reserve 1 | B34: =SUM(F34:AR34) -> 39 | C34: =SUM(F34:AR34) -> 39 | F34: {=SUM(IF(F3:F32="R",1,0))} -> 1 | G34: {=SUM(IF(G3:G32="R",1,0))} -> 1 | H34: {=SUM(IF(H3:H32="R",1,0))} -> 1 | I34: {=SUM(IF(I3:I32="R",1,0))} -> 1 | J34: {=SUM(IF(J3:J32="R",1,0))} -> 1 | K34: {=SUM(IF(K3:K32="R",1,0))} -> 1 | L34: {=SUM(IF(L3:L32="R",1,0))} -> 1 | M34: {=SUM(IF(M3:M32="R",1,0))} -> 1 | ... AR34: {=SUM(IF(AR3:AR32="R",1,0))} -> 1
A35: Reserve 2 | B35: =SUM(F35:AR35) -> 39 | C35: =SUM(F35:AR35) -> 39 | F35: {=SUM(IF(F3:F32="R2",1,0))} -> 1 | G35: {=SUM(IF(G3:G32="R2",1,0))} -> 1 | H35: {=SUM(IF(H3:H32="R2",1,0))} -> 1 | I35: {=SUM(IF(I3:I32="R2",1,0))} -> 1 | J35: {=SUM(IF(J3:J32="R2",1,0))} -> 1 | K35: {=SUM(IF(K3:K32="R2",1,0))} -> 1 | L35: {=SUM(IF(L3:L32="R2",1,0))} -> 1 | M35: {=SUM(IF(M3:M32="R2",1,0))} -> 1 | ... AR35: {=SUM(IF(AR3:AR32="R2",1,0))} -> 1
E36: Duty Clerk | F36: =IFERROR(INDEX($A$3:$A$32, MATCH(1, INDEX($F$3:$AR$32, 0, MATCH(F2, $F$2:$AR$2, 0)), 0)), INDEX($A$3:$A$32, MATCH(1, INDEX($F$3:$AR$32, 0, MATCH(F2&" AM", $F$2:$AR$2, 0)), 0))) -> PTE DARREN | G36: =IFERROR(INDEX($A$3:$A$32, MATCH(1, INDEX($F$3:$AR$32, 0, MATCH(G2, $F$2:$AR$2, 0)), 0)), INDEX($A$3:$A$32, MATCH(1, INDEX($F$3:$AR$32, 0, MATCH(G2&" AM", $F$2:$AR$2, 0)), 0))) -> PTE JIREH | H36: =IFERROR(INDEX($A$3:$A$32, MATCH(1, INDEX($F$3:$AR$32, 0, MATCH(H2, $F$2:$AR$2, 0)), 0)), INDEX($A$3:$A$32, MATCH(1, INDEX($F$3:$AR$32, 0, MATCH(H2&" AM", $F$2:$AR$2, 0)), 0))) -> PTE ERNEST | I36: =IFERROR(INDEX($A$3:$A$32, MATCH(1, INDEX($F$3:$AR$32, 0, MATCH(I2, $F$2:$AR$2, 0)), 0)), INDEX($A$3:$A$32, MATCH(1, INDEX($F$3:$AR$32, 0, MATCH(I2&" AM", $F$2:$AR$2, 0)), 0))) -> PTE HAQIMI | J36: =IFERROR(INDEX($A$3:$A$32, MATCH(1, INDEX($F$3:$AR$32, 0, MATCH(J2, $F$2:$AR$2, 0)), 0)), INDEX($A$3:$A$32, MATCH(1, INDEX($F$3:$AR$32, 0, MATCH(J2&" AM", $F$2:$AR$2, 0)), 0))) -> PTE AMIN | K36: =IFERROR(INDEX($A$3:$A$32, MATCH(1, INDEX($F$3:$AR$32, 0, MATCH(K2, $F$2:$AR$2, 0)), 0)), INDEX($A$3:$A$32, MATCH(1, INDEX($F$3:$AR$32, 0, MATCH(K2&" AM", $F$2:$AR$2, 0)), 0))) -> PTE RIFQI | L36: =IFERROR(INDEX($A$3:$A$32, MATCH(1, INDEX($F$3:$AR$32, 0, MATCH(L2, $F$2:$AR$2, 0)), 0)), INDEX($A$3:$A$32, MATCH(1, INDEX($F$3:$AR$32, 0, MATCH(L2&" AM", $F$2:$AR$2, 0)), 0))) -> PTE LI HUI | M36: =IFERROR(INDEX($A$3:$A$32, MATCH(1, INDEX($F$3:$AR$32, 0, MATCH(M2, $F$2:$AR$2, 0)), 0)), INDEX($A$3:$A$32, MATCH(1, INDEX($F$3:$AR$32, 0, MATCH(M2&" AM", $F$2:$AR$2, 0)), 0))) -> PTE EZRA | ... AR36: =IFERROR(INDEX($A$3:$A$32, MATCH(1, INDEX($F$3:$AR$32, 0, MATCH(AR2, $F$2:$AR$2, 0)), 0)), INDEX($A$3:$A$32, MATCH(1, INDEX($F$3:$AR$32, 0, MATCH(AR2&" AM", $F$2:$AR$2, 0)), 0))) -> PTE HOI REI
E37: Reserve | F37: =INDEX($A$3:$A$32, MATCH("R", INDEX($F$3:$AR$32, 0, MATCH(F2, $F$2:$AR$2, 0)), 0)) -> PTE XIAO YU | G37: =INDEX($A$3:$A$32, MATCH("R", INDEX($F$3:$AR$32, 0, MATCH(G2, $F$2:$AR$2, 0)), 0)) -> PTE AMIN | H37: =INDEX($A$3:$A$32, MATCH("R", INDEX($F$3:$AR$32, 0, MATCH(H2, $F$2:$AR$2, 0)), 0)) -> PTE DARREN | I37: =INDEX($A$3:$A$32, MATCH("R", INDEX($F$3:$AR$32, 0, MATCH(I2, $F$2:$AR$2, 0)), 0)) -> PTE ERNEST | J37: =INDEX($A$3:$A$32, MATCH("R", INDEX($F$3:$AR$32, 0, MATCH(J2, $F$2:$AR$2, 0)), 0)) -> REC ETHAN | K37: =INDEX($A$3:$A$32, MATCH("R", INDEX($F$3:$AR$32, 0, MATCH(K2, $F$2:$AR$2, 0)), 0)) -> PTE LI HUI | L37: =INDEX($A$3:$A$32, MATCH("R", INDEX($F$3:$AR$32, 0, MATCH(L2, $F$2:$AR$2, 0)), 0)) -> PTE ADAM | M37: =INDEX($A$3:$A$32, MATCH("R", INDEX($F$3:$AR$32, 0, MATCH(M2, $F$2:$AR$2, 0)), 0)) -> REC PARAM | ... AR37: =INDEX($A$3:$A$32, MATCH("R", INDEX($F$3:$AR$32, 0, MATCH(AR2, $F$2:$AR$2, 0)), 0)) -> PTE EZRA
E38: Reserve 2 | F38: =INDEX($A$3:$A$32, MATCH("R2", INDEX($F$3:$AR$32, 0, MATCH(F2, $F$2:$AR$2, 0)), 0)) -> CPL YUSUF | G38: =INDEX($A$3:$A$32, MATCH("R2", INDEX($F$3:$AR$32, 0, MATCH(G2, $F$2:$AR$2, 0)), 0)) -> PTE REUVEN | H38: =INDEX($A$3:$A$32, MATCH("R2", INDEX($F$3:$AR$32, 0, MATCH(H2, $F$2:$AR$2, 0)), 0)) -> REC ETHAN | I38: =INDEX($A$3:$A$32, MATCH("R2", INDEX($F$3:$AR$32, 0, MATCH(I2, $F$2:$AR$2, 0)), 0)) -> PTE JIREH | J38: =INDEX($A$3:$A$32, MATCH("R2", INDEX($F$3:$AR$32, 0, MATCH(J2, $F$2:$AR$2, 0)), 0)) -> PTE EZRA | K38: =INDEX($A$3:$A$32, MATCH("R2", INDEX($F$3:$AR$32, 0, MATCH(K2, $F$2:$AR$2, 0)), 0)) -> PTE HAQIMI | L38: =INDEX($A$3:$A$32, MATCH("R2", INDEX($F$3:$AR$32, 0, MATCH(L2, $F$2:$AR$2, 0)), 0)) -> PTE FIRMAN | M38: =INDEX($A$3:$A$32, MATCH("R2", INDEX($F$3:$AR$32, 0, MATCH(M2, $F$2:$AR$2, 0)), 0)) -> PTE RIFQI | ... AR38: =INDEX($A$3:$A$32, MATCH("R2", INDEX($F$3:$AR$32, 0, MATCH(AR2, $F$2:$AR$2, 0)), 0)) -> PTE DARREN

Sheet August Master Duty Overview
A1: Duty Personnel Duty | B1: Total Points | C1: Duty Points | D1: Reserve Points | E1: Reserve Points 2 | F1: THURSDAY | G1: FRIDAY | H1: SATURDAY (AM) | I1: SATURDAY (PM) | J1: SUNDAY (AM) | K1: SUNDAY (PM) | L1: MONDAY | M1: TUESDAY | N1: WEDNESDAY | O1: THURSDAY | P1: FRIDAY (AM) | Q1: FRIDAY (PM) | R1: SATURDAY (AM) | S1: SATURDAY (PM) | T1: SUNDAY (AM) | U1: SUNDAY (PM) | V1: MONDAY | W1: TUESDAY | X1: WEDNESDAY | Y1: THURSDAY | Z1: FRIDAY | AA1: SATURDAY (AM) | AB1: SATURDAY (PM) | AC1: SUNDAY (AM) | AD1: SUNDAY (PM) | AE1: MONDAY | AF1: TUESDAY | AG1: WEDNESDAY | AH1: THURSDAY | AI1: FRIDAY | AJ1: SATURDAY (AM) | AK1: SATURDAY (PM) | AL1: SUNDAY (AM) | AM1: SUNDAY (PM) | AN1: MONDAY | AO1: TUESDAY | AP1: WEDNESDAY | AQ1: THURSDAY | AR1: FRIDAY | AS1: SATURDAY (AM) | AT1: SATURDAY (PM)
F2: 45505 | G2: 45506 | H2: 3-8-24 (AM) | I2: 3-8-24 (PM) | J2: 4-8-24 (AM) | K2: 4-8-24 (PM) | L2: 45509 | M2: 45510 | N2: 45511 | O2: 45512 | P2: 9-8-24 (AM) | Q2: 9-8-24 (PM) | R2: 10-8-24 (AM) | S2: 10-8-24 (PM) | T2: 11-8-24 (AM) | U2: 11-8-24 (PM) | V2: 45516 | W2: 45517 | X2: 45518 | Y2: 45519 | Z2: 45520 | AA2: 17-8-24 (AM) | AB2: 17-8-24 (PM) | AC2: 18-8-24 (AM) | AD2: 18-8-24 (PM) | AE2: 45523 | AF2: 45524 | AG2: 45525 | AH2: 45526 | AI2: 45527 | AJ2: 24-8-24 (AM) | AK2: 24-8-24 (PM) | AL2: 25-8-24 (AM) | AM2: 25-8-24 (PM) | AN2: 45530 | AO2: 45531 | AP2: 45532 | AQ2: 45533 | AR2: 45534 | AS2: 31-8-24 (AM) | AT2: 31-8-24 (PM)
A3: PTE EZRA | B3: =SUM(C3:D3) -> 4 | C3: =SUM(F3:AT3) -> 2 | D3: {=SUM(IF(F3:AT3="R",1,0))} -> 2 | E3: {=SUM(IF(F3:AT3="R2",1,0))} -> 2 | G3: r2 | H3: r2 | P3: 1 | V3: r | AM3: 1 | AR3: r
A4: LCP ERNEST | B4: =SUM(C4:D4) -> 5 | C4: =SUM(F4:AT4) -> 2 | D4: {=SUM(IF(F4:AT4="R",1,0))} -> 3 | E4: {=SUM(IF(F4:AT4="R2",1,0))} -> 2 | I4: 1 | K4: r | S4: r | Y4: r | AB4: r2 | AO4: r2 | AT4: 1
A5: PTE FIRMAN | B5: =SUM(C5:D5) -> 4 | C5: =SUM(F5:AT5) -> 2 | D5: {=SUM(IF(F5:AT5="R",1,0))} -> 2 | E5: {=SUM(IF(F5:AT5="R2",1,0))} -> 2 | I5: r | K5: r2 | M5: r | S5: 1 | AB5: 1 | AP5: r2
A6: PTE AFIF | B6: =SUM(C6:D6) -> 4 | C6: =SUM(F6:AT6) -> 2 | D6: {=SUM(IF(F6:AT6="R",1,0))} -> 2 | E6: {=SUM(IF(F6:AT6="R2",1,0))} -> 3 | I6: r2 | O6: r2 | R6: 1 | V6: 1 | AB6: r | AE6: r2 | AP6: r
A7: PTE ADAM | B7: =SUM(C7:D7) -> 5 | C7: =SUM(F7:AT7) -> 2 | D7: {=SUM(IF(F7:AT7="R",1,0))} -> 3 | E7: {=SUM(IF(F7:AT7="R2",1,0))} -> 2 | M7: r2 | Q7: 1 | U7: r | W7: r | AA7: r | AC7: r2 | AD7: 1
A8: LCP AMIRUL | B8: =SUM(C8:D8) -> 0 | C8: =SUM(F8:AT8) -> 0 | D8: {=SUM(IF(F8:AT8="R",1,0))} -> 0 | E8: {=SUM(IF(F8:AT8="R2",1,0))} -> 0
A9: CPL DANIEL | B9: =SUM(C9:D9) -> 5 | C9: =SUM(F9:AT9) -> 3 | D9: {=SUM(IF(F9:AT9="R",1,0))} -> 2 | E9: {=SUM(IF(F9:AT9="R2",1,0))} -> 2 | G9: 1 | Q9: r2 | AE9: 1 | AI9: 1 | AN9: r | AQ9: r2 | AT9: r
A10: PTE ANGELO | B10: =SUM(C10:D10) -> 4 | C10: =SUM(F10:AT10) -> 2 | D10: {=SUM(IF(F10:AT10="R",1,0))} -> 2 | E10: {=SUM(IF(F10:AT10="R2",1,0))} -> 2 | G10: r | W10: 1 | AA10: r2 | AF10: 1 | AH10: r | AI10: r2
A11: REC RUI FENG | B11: =SUM(C11:D11) -> 4 | C11: =SUM(F11:AT11) -> 2 | D11: {=SUM(IF(F11:AT11="R",1,0))} -> 2 | E11: {=SUM(IF(F11:AT11="R2",1,0))} -> 2 | R11: r | T11: r2 | AA11: 1 | AC11: r | AL11: 1 | AS11: r2
A12: PTE MATTHEW | B12: =SUM(C12:D12) -> 0 | C12: =SUM(F12:AT12) -> 0 | D12: {=SUM(IF(F12:AT12="R",1,0))} -> 0 | E12: {=SUM(IF(F12:AT12="R2",1,0))} -> 0
A13: REC ETHAN | B13: =SUM(C13:D13) -> 4 | C13: =SUM(F13:AT13) -> 2 | D13: {=SUM(IF(F13:AT13="R",1,0))} -> 2 | E13: {=SUM(IF(F13:AT13="R2",1,0))} -> 2 | AE13: r | AF13: r2 | AG13: 1 | AI13: r | AM13: r2 | AN13: 1
A14: PTE AMIN | C14: =SUM(F14:AT14) -> 3 | D14: {=SUM(IF(F14:AT14="R",1,0))} -> 2 | E14: {=SUM(IF(F14:AT14="R2",1,0))} -> 2 | H14: r | L14: 1 | O14: r | U14: 1 | V14: r2 | X14: r2 | Z14: 1
A15: PTE JASPER | B15: =SUM(C15:D15) -> 0 | C15: =SUM(F15:AT15) -> 0 | D15: {=SUM(IF(F15:AT15="R",1,0))} -> 0 | E15: {=SUM(IF(F15:AT15="R2",1,0))} -> 0
A16: REC PARAM | C16: =SUM(F16:AT16) -> 2 | D16: {=SUM(IF(F16:AT16="R",1,0))} -> 2 | E16: {=SUM(IF(F16:AT16="R2",1,0))} -> 2 | J16: 1 | R16: r2 | T16: r | AJ16: r | AL16: r2 | AS16: 1
A17: PTE RIFQI | B17: =SUM(C17:D17) -> 4 | C17: =SUM(F17:AT17) -> 2 | D17: {=SUM(IF(F17:AT17="R",1,0))} -> 2 | E17: {=SUM(IF(F17:AT17="R2",1,0))} -> 2 | H17: 1 | P17: r2 | AC17: 1 | AJ17: r2 | AL17: r | AS17: r
A18: PTE HAQIMI | B18: =SUM(C18:D18) -> 4 | C18: =SUM(F18:AT18) -> 2 | D18: {=SUM(IF(F18:AT18="R",1,0))} -> 2 | E18: {=SUM(IF(F18:AT18="R2",1,0))} -> 3 | F18: r2 | J18: r2 | K18: 1 | N18: 1 | AG18: r2 | AK18: r | AM18: r
A19: PTE DARREN | B19: =SUM(C19:D19) -> 4 | C19: =SUM(F19:AT19) -> 2 | D19: {=SUM(IF(F19:AT19="R",1,0))} -> 2 | E19: {=SUM(IF(F19:AT19="R2",1,0))} -> 2 | F19: 1 | L19: r2 | N19: r | X19: 1 | AK19: r2 | AO19: r
A20: PTE SAMEER | B20: =SUM(C20:D20) -> 0 | C20: =SUM(F20:AT20) -> 0 | D20: {=SUM(IF(F20:AT20="R",1,0))} -> 0 | E20: {=SUM(IF(F20:AT20="R2",1,0))} -> 0
A21: PTE XIAO YU | B21: =SUM(C21:D21) -> 4 | C21: =SUM(F21:AT21) -> 2 | D21: {=SUM(IF(F21:AT21="R",1,0))} -> 2 | E21: {=SUM(IF(F21:AT21="R2",1,0))} -> 2 | F21: r | N21: r2 | Y21: 1 | AD21: r | AR21: 1 | AT21: r2
A22: SCT YUSUF | C22: =SUM(F22:AT22) -> 2 | D22: {=SUM(IF(F22:AT22="R",1,0))} -> 2 | E22: {=SUM(IF(F22:AT22="R2",1,0))} -> 2 | L22: r | O22: 1 | AH22: 1 | AN22: r2 | AQ22: r | AR22: r2
A23: PTE HOI REI | C23: =SUM(F23:AT23) -> 3 | D23: {=SUM(IF(F23:AT23="R",1,0))} -> 2 | E23: {=SUM(IF(F23:AT23="R2",1,0))} -> 2 | M23: 1 | P23: r | Y23: r2 | AD23: r2 | AG23: r | AJ23: 1 | AO23: 1
A24: PTE REUVEN | B24: =SUM(C24:D24) -> 0 | C24: =SUM(F24:AT24) -> 0 | D24: {=SUM(IF(F24:AT24="R",1,0))} -> 0 | E24: {=SUM(IF(F24:AT24="R2",1,0))} -> 0
A25: PTE HAO QIAN | B25: =SUM(C25:D25) -> 5 | C25: =SUM(F25:AT25) -> 2 | D25: {=SUM(IF(F25:AT25="R",1,0))} -> 3 | E25: {=SUM(IF(F25:AT25="R2",1,0))} -> 2 | J25: r | Q25: r | S25: r2 | T25: 1 | U25: r2 | Z25: r | AP25: 1
A26: PTE JIREH | B26: =SUM(C26:D26) -> 4 | C26: =SUM(F26:AT26) -> 2 | D26: {=SUM(IF(F26:AT26="R",1,0))} -> 2 | E26: {=SUM(IF(F26:AT26="R2",1,0))} -> 3 | W26: r2 | X26: r | Z26: r2 | AF26: r | AH26: r2 | AK26: 1 | AQ26: 1
A27: Total | B27: =SUM(B4:B13) -> 35 | C27: =SUM(F27:AT27) -> 41 | F27: =SUM(F3:F26) -> 1 | G27: =SUM(G3:G26) -> 1 | H27: =SUM(H3:H26) -> 1 | I27: =SUM(I3:I26) -> 1 | J27: =SUM(J3:J26) -> 1 | K27: =SUM(K3:K26) -> 1 | L27: =SUM(L3:L26) -> 1 | M27: =SUM(M3:M26) -> 1 | ... AT27: =SUM(AT3:AT26) -> 1
A28: Reserve 1 | B28: =SUM(F28:AR28) -> 39 | C28: =SUM(F28:AT28) -> 41 | F28: {=SUM(IF(F3:F26="R",1,0))} -> 1 | G28: {=SUM(IF(G3:G26="R",1,0))} -> 1 | H28: {=SUM(IF(H3:H26="R",1,0))} -> 1 | I28: {=SUM(IF(I3:I26="R",1,0))} -> 1 | J28: {=SUM(IF(J3:J26="R",1,0))} -> 1 | K28: {=SUM(IF(K3:K26="R",1,0))} -> 1 | L28: {=SUM(IF(L3:L26="R",1,0))} -> 1 | M28: {=SUM(IF(M3:M26="R",1,0))} -> 1 | ... AT28: {=SUM(IF(AT3:AT26="R",1,0))} -> 1
A29: Reserve 2 | B29: =SUM(F29:AR29) -> 39 | C29: =SUM(F29:AT29) -> 41 | F29: {=SUM(IF(F3:F26="R2",1,0))} -> 1 | G29: {=SUM(IF(G3:G26="R2",1,0))} -> 1 | H29: {=SUM(IF(H3:H26="R2",1,0))} -> 1 | I29: {=SUM(IF(I3:I26="R2",1,0))} -> 1 | J29: {=SUM(IF(J3:J26="R2",1,0))} -> 1 | K29: {=SUM(IF(K3:K26="R2",1,0))} -> 1 | L29: {=SUM(IF(L3:L26="R2",1,0))} -> 1 | M29: {=SUM(IF(M3:M26="R2",1,0))} -> 1 | ... AT29: {=SUM(IF(AT3:AT26="R2",1,0))} -> 1
E30: Duty Clerk | F30: =IFERROR(INDEX($A$3:$A$26, MATCH(1, INDEX($F$3:$AT$26, 0, MATCH(F2, $F$2:$AT$2, 0)), 0)), INDEX($A$3:$A$26, MATCH(1, INDEX($F$3:$AT$26, 0, MATCH(F2&" AM", $F$2:$AT$2, 0)), 0))) -> PTE DARREN | G30: =IFERROR(INDEX($A$3:$A$26, MATCH(1, INDEX($F$3:$AT$26, 0, MATCH(G2, $F$2:$AT$2, 0)), 0)), INDEX($A$3:$A$26, MATCH(1, INDEX($F$3:$AT$26, 0, MATCH(G2&" AM", $F$2:$AT$2, 0)), 0))) -> CPL DANIEL | H30: =IFERROR(INDEX($A$3:$A$26, MATCH(1, INDEX($F$3:$AT$26, 0, MATCH(H2, $F$2:$AT$2, 0)), 0)), INDEX($A$3:$A$26, MATCH(1, INDEX($F$3:$AT$26, 0, MATCH(H2&" AM", $F$2:$AT$2, 0)), 0))) -> PTE RIFQI | I30: =IFERROR(INDEX($A$3:$A$26, MATCH(1, INDEX($F$3:$AT$26, 0, MATCH(I2, $F$2:$AT$2, 0)), 0)), INDEX($A$3:$A$26, MATCH(1, INDEX($F$3:$AT$26, 0, MATCH(I2&" AM", $F$2:$AT$2, 0)), 0))) -> LCP ERNEST | J30: =IFERROR(INDEX($A$3:$A$26, MATCH(1, INDEX($F$3:$AT$26, 0, MATCH(J2, $F$2:$AT$2, 0)), 0)), INDEX($A$3:$A$26, MATCH(1, INDEX($F$3:$AT$26, 0, MATCH(J2&" AM", $F$2:$AT$2, 0)), 0))) -> REC PARAM | K30: =IFERROR(INDEX($A$3:$A$26, MATCH(1, INDEX($F$3:$AT$26, 0, MATCH(K2, $F$2:$AT$2, 0)), 0)), INDEX($A$3:$A$26, MATCH(1, INDEX($F$3:$AT$26, 0, MATCH(K2&" AM", $F$2:$AT$2, 0)), 0))) -> PTE HAQIMI | L30: =IFERROR(INDEX($A$3:$A$26, MATCH(1, INDEX($F$3:$AT$26, 0, MATCH(L2, $F$2:$AT$2, 0)), 0)), INDEX($A$3:$A$26, MATCH(1, INDEX($F$3:$AT$26, 0, MATCH(L2&" AM", $F$2:$AT$2, 0)), 0))) -> PTE AMIN | M30: =IFERROR(INDEX($A$3:$A$26, MATCH(1, INDEX($F$3:$AT$26, 0, MATCH(M2, $F$2:$AT$2, 0)), 0)), INDEX($A$3:$A$26, MATCH(1, INDEX($F$3:$AT$26, 0, MATCH(M2&" AM", $F$2:$AT$2, 0)), 0))) -> PTE HOI REI | ... AT30: =IFERROR(INDEX($A$3:$A$26, MATCH(1, INDEX($F$3:$AT$26, 0, MATCH(AT2, $F$2:$AT$2, 0)), 0)), INDEX($A$3:$A$26, MATCH(1, INDEX($F$3:$AT$26, 0, MATCH(AT2&" AM", $F$2:$AT$2, 0)), 0))) -> LCP ERNEST
E31: Reserve | F31: =INDEX($A$3:$A$26, MATCH("R", INDEX($F$3:$AT$26, 0, MATCH(F2, $F$2:$AT$2, 0)), 0)) -> PTE XIAO YU | G31: =INDEX($A$3:$A$26, MATCH("R", INDEX($F$3:$AT$26, 0, MATCH(G2, $F$2:$AT$2, 0)), 0)) -> PTE ANGELO | H31: =INDEX($A$3:$A$26, MATCH("R", INDEX($F$3:$AT$26, 0, MATCH(H2, $F$2:$AT$2, 0)), 0)) -> PTE AMIN | I31: =INDEX($A$3:$A$26, MATCH("R", INDEX($F$3:$AT$26, 0, MATCH(I2, $F$2:$AT$2, 0)), 0)) -> PTE FIRMAN | J31: =INDEX($A$3:$A$26, MATCH("R", INDEX($F$3:$AT$26, 0, MATCH(J2, $F$2:$AT$2, 0)), 0)) -> PTE HAO QIAN | K31: =INDEX($A$3:$A$26, MATCH("R", INDEX($F$3:$AT$26, 0, MATCH(K2, $F$2:$AT$2, 0)), 0)) -> LCP ERNEST | L31: =INDEX($A$3:$A$26, MATCH("R", INDEX($F$3:$AT$26, 0, MATCH(L2, $F$2:$AT$2, 0)), 0)) -> SCT YUSUF | M31: =INDEX($A$3:$A$26, MATCH("R", INDEX($F$3:$AT$26, 0, MATCH(M2, $F$2:$AT$2, 0)), 0)) -> PTE FIRMAN | ... AT31: =INDEX($A$3:$A$26, MATCH("R", INDEX($F$3:$AT$26, 0, MATCH(AT2, $F$2:$AT$2, 0)), 0)) -> CPL DANIEL
E32: Reserve 2 | F32: =INDEX($A$3:$A$26, MATCH("R2", INDEX($F$3:$AT$26, 0, MATCH(F2, $F$2:$AT$2, 0)), 0)) -> PTE HAQIMI | G32: =INDEX($A$3:$A$26, MATCH("R2", INDEX($F$3:$AT$26, 0, MATCH(G2, $F$2:$AT$2, 0)), 0)) -> PTE EZRA | H32: =INDEX($A$3:$A$26, MATCH("R2", INDEX($F$3:$AT$26, 0, MATCH(H2, $F$2:$AT$2, 0)), 0)) -> PTE EZRA | I32: =INDEX($A$3:$A$26, MATCH("R2", INDEX($F$3:$AT$26, 0, MATCH(I2, $F$2:$AT$2, 0)), 0)) -> PTE AFIF | J32: =INDEX($A$3:$A$26, MATCH("R2", INDEX($F$3:$AT$26, 0, MATCH(J2, $F$2:$AT$2, 0)), 0)) -> PTE HAQIMI | K32: =INDEX($A$3:$A$26, MATCH("R2", INDEX($F$3:$AT$26, 0, MATCH(K2, $F$2:$AT$2, 0)), 0)) -> PTE FIRMAN | L32: =INDEX($A$3:$A$26, MATCH("R2", INDEX($F$3:$AT$26, 0, MATCH(L2, $F$2:$AT$2, 0)), 0)) -> PTE DARREN | M32: =INDEX($A$3:$A$26, MATCH("R2", INDEX($F$3:$AT$26, 0, MATCH(M2, $F$2:$AT$2, 0)), 0)) -> PTE ADAM | ... AT32: =INDEX($A$3:$A$26, MATCH("R2", INDEX($F$3:$AT$26, 0, MATCH(AT2, $F$2:$AT$2, 0)), 0)) -> PTE XIAO YU
A36: Excuse Stay in
A37: PA
A38: R&D
A39: RM
A40: PR
A41: MEDIA
A42: TCRS 3
A43: OPS RM
...

Sheet September Master Duty Overview
B1: Total Points | C1: Duty Points | D1: Reserve Points | E1: Reserve Points 2 | F1: SUNDAY (AM) | G1: SUNDAY (PM) | H1: MONDAY | I1: TUESDAY | J1: WEDNESDAY | K1: THURSDAY | L1: FRIDAY | M1: SATURDAY (AM) | N1: SATURDAY (PM) | O1: SUNDAY (AM) | P1: SUNDAY (PM) | Q1: MONDAY | R1: TUESDAY | S1: WEDNESDAY | T1: THURSDAY | U1: FRIDAY | V1: SATURDAY (AM) | W1: SATURDAY (PM) | X1: SUNDAY (AM) | Y1: SUNDAY (PM) | Z1: MONDAY | AA1: TUESDAY | AB1: WEDNESDAY | AC1: THURSDAY | AD1: FRIDAY | AE1: SATURDAY (AM) | AF1: SATURDAY (PM) | AG1: SUNDAY (AM) | AH1: SUNDAY (PM) | AI1: MONDAY | AJ1: TUESDAY | AK1: WEDNESDAY | AL1: THURSDAY | AM1: FRIDAY | AN1: SATURDAY (AM) | AO1: SATURDAY (PM) | AP1: SUNDAY (AM) | AQ1: SUNDAY (PM) | AR1: MONDAY
F2: 1-9-24 (AM) | G2: 1-9-24 (PM) | H2: 45537 | I2: 45538 | J2: 45539 | K2: 45540 | L2: 45541 | M2: 7-9-24 (AM) | N2: 7-9-24 (PM) | O2: 8-9-24 (AM) | P2: 8-9-24 (PM) | Q2: 45544 | R2: 45545 | S2: 45546 | T2: 45547 | U2: 45548 | V2: 14-9-24 (AM) | W2: 14-9-24 (PM) | X2: 15-9-24 (AM) | Y2: 15-9-24 (PM) | Z2: 45551 | AA2: 45552 | AB2: 45553 | AC2: 45554 | AD2: 45555 | AE2: 21-9-24 (AM) | AF2: 21-9-24 (PM) | AG2: 22-9-24 (AM) | AH2: 22-9-24 (PM) | AI2: 45527 | AJ2: 45528 | AK2: 45529 | AL2: 45530 | AM2: 45531 | AN2: 28-9-24 (AM) | AO2: 28-9-24 (PM) | AP2: 29-9-24 (AM) | AQ2: 29-9-24 (PM) | AR2: 45565
A3: PTE EZRA | B3: =SUM(C3:D3) -> 3 | C3: =SUM(F3:AR3) -> 1 | D3: {=SUM(IF(F3:AR3="R",1,0))} -> 2 | E3: {=SUM(IF(F3:AR3="R2",1,0))} -> 2 | L3: r | N3: r2 | P3: 1 | T3: r | Y3: r2
A4: LCP ERNEST | B4: =SUM(C4:D4) -> 2 | C4: =SUM(F4:AR4) -> 1 | D4: {=SUM(IF(F4:AR4="R",1,0))} -> 1 | E4: {=SUM(IF(F4:AR4="R2",1,0))} -> 2 | H4: r2 | V4: r | AC4: 1 | AF4: r2
A5: LCP FIRMAN | B5: =SUM(C5:D5) -> 2 | C5: =SUM(F5:AR5) -> 1 | D5: {=SUM(IF(F5:AR5="R",1,0))} -> 1 | E5: {=SUM(IF(F5:AR5="R2",1,0))} -> 2 | T5: r2 | AB5: r2 | AC5: r | AF5: 1
A6: PTE AFIF | B6: =SUM(C6:D6) -> 2 | C6: =SUM(F6:AR6) -> 1 | D6: {=SUM(IF(F6:AR6="R",1,0))} -> 1 | E6: {=SUM(IF(F6:AR6="R2",1,0))} -> 2 | R6: r2 | AC6: r2 | AF6: r | AI6: 1
A7: LCP ADAM | B7: =SUM(C7:D7) -> 3 | C7: =SUM(F7:AR7) -> 1 | D7: {=SUM(IF(F7:AR7="R",1,0))} -> 2 | E7: {=SUM(IF(F7:AR7="R2",1,0))} -> 2 | I7: r2 | P7: r2 | U7: r | W7: r | Y7: 1
A8: LCP AMIRUL | B8: =SUM(C8:D8) -> 4 | C8: =SUM(F8:AR8) -> 2 | D8: {=SUM(IF(F8:AR8="R",1,0))} -> 2 | E8: {=SUM(IF(F8:AR8="R2",1,0))} -> 2 | H8: 1 | U8: 1 | W8: r2 | Y8: r | AL8: r | AN8: r2
A9: SCT DANIEL | B9: =SUM(C9:D9) -> 3 | C9: =SUM(F9:AR9) -> 1 | D9: {=SUM(IF(F9:AR9="R",1,0))} -> 2 | E9: {=SUM(IF(F9:AR9="R2",1,0))} -> 1 | G9: r2 | J9: r | AJ9: r | AL9: 1
A10: PTE ANGELO | B10: =SUM(C10:D10) -> 4 | C10: =SUM(F10:AR10) -> 2 | D10: {=SUM(IF(F10:AR10="R",1,0))} -> 2 | E10: {=SUM(IF(F10:AR10="R2",1,0))} -> 1 | I10: r | W10: 1 | AJ10: 1 | AM10: r2 | AO10: r
A11: REC RUI FENG | B11: =SUM(C11:D11) -> 4 | C11: =SUM(F11:AR11) -> 2 | D11: {=SUM(IF(F11:AR11="R",1,0))} -> 2 | E11: {=SUM(IF(F11:AR11="R2",1,0))} -> 1 | F11: r2 | V11: 1 | AE11: r | AN11: 1 | AP11: r
A12: PTE MATTHEW | B12: =SUM(C12:D12) -> 0 | C12: =SUM(F12:AR12) -> 0 | D12: {=SUM(IF(F12:AR12="R",1,0))} -> 0 | E12: {=SUM(IF(F12:AR12="R2",1,0))} -> 0
A13: REC ETHAN | B13: =SUM(C13:D13) -> 0 | C13: =SUM(F13:AR13) -> 0 | D13: {=SUM(IF(F13:AR13="R",1,0))} -> 0 | E13: {=SUM(IF(F13:AR13="R2",1,0))} -> 0
A14: PTE AMIN | C14: =SUM(F14:AR14) -> 2 | D14: {=SUM(IF(F14:AR14="R",1,0))} -> 2 | E14: {=SUM(IF(F14:AR14="R2",1,0))} -> 2 | J14: r2 | K14: r | L14: 1 | AB14: r | AG14: r2 | AH14: 1
A15: PTE JASPER | B15: =SUM(C15:D15) -> 4 | C15: =SUM(F15:AR15) -> 2 | D15: {=SUM(IF(F15:AR15="R",1,0))} -> 2 | E15: {=SUM(IF(F15:AR15="R2",1,0))} -> 2 | F15: r | J15: 1 | K15: r2 | M15: r2 | AB15: 1 | AN15: r
A16: REC PARAM | C16: =SUM(F16:AR16) -> 2 | D16: {=SUM(IF(F16:AR16="R",1,0))} -> 1 | E16: {=SUM(IF(F16:AR16="R2",1,0))} -> 1 | M16: 1 | O16: r2 | X16: r | AG16: 1
A17: PTE RIFQI | B17: =SUM(C17:D17) -> 4 | C17: =SUM(F17:AR17) -> 2 | D17: {=SUM(IF(F17:AR17="R",1,0))} -> 2 | E17: {=SUM(IF(F17:AR17="R2",1,0))} -> 1 | M17: r | O17: 1 | X17: r2 | AG17: r | AP17: 1
A18: REC ASH | C18: =SUM(F18:AR18) -> 2 | D18: {=SUM(IF(F18:AR18="R",1,0))} -> 1 | E18: {=SUM(IF(F18:AR18="R2",1,0))} -> 2 | F18: 1 | O18: r | V18: r2 | X18: 1 | AP18: r2
A19: PTE HAQIMI | B19: =SUM(C19:D19) -> 3 | C19: =SUM(F19:AR19) -> 1 | D19: {=SUM(IF(F19:AR19="R",1,0))} -> 2 | E19: {=SUM(IF(F19:AR19="R2",1,0))} -> 1 | K19: 1 | N19: r | Q19: r | AA19: r2
A20: PTE DARREN | B20: =SUM(C20:D20) -> 3 | C20: =SUM(F20:AR20) -> 2 | D20: {=SUM(IF(F20:AR20="R",1,0))} -> 1 | E20: {=SUM(IF(F20:AR20="R2",1,0))} -> 2 | Q20: 1 | S20: r2 | AA20: r | AD20: r2 | AM20: 1
A21: PTE SAMEER | B21: =SUM(C21:D21) -> 4 | C21: =SUM(F21:AR21) -> 2 | D21: {=SUM(IF(F21:AR21="R",1,0))} -> 2 | E21: {=SUM(IF(F21:AR21="R2",1,0))} -> 2 | Q21: r2 | S21: r | AA21: 1 | AE21: 1 | AH21: r | AL21: r2
A22: PTE XIAO YU | B22: =SUM(C22:D22) -> 4 | C22: =SUM(F22:AR22) -> 2 | D22: {=SUM(IF(F22:AR22="R",1,0))} -> 2 | E22: {=SUM(IF(F22:AR22="R2",1,0))} -> 2 | Z22: 1 | AE22: r2 | AI22: r2 | AM22: r | AO22: 1 | AQ22: r
A23: SCT YUSUF | C23: =SUM(F23:AR23) -> 0 | D23: {=SUM(IF(F23:AR23="R",1,0))} -> 0 | E23: {=SUM(IF(F23:AR23="R2",1,0))} -> 0
A24: PTE HOI REI | C24: =SUM(F24:AR24) -> 2 | D24: {=SUM(IF(F24:AR24="R",1,0))} -> 2 | E24: {=SUM(IF(F24:AR24="R2",1,0))} -> 2 | I24: 1 | S24: 1 | Z24: r | AH24: r2 | AI24: r | AR24: r2
A25: PTE REUVEN | B25: =SUM(C25:D25) -> 0 | C25: =SUM(F25:AR25) -> 0 | D25: {=SUM(IF(F25:AR25="R",1,0))} -> 0 | E25: {=SUM(IF(F25:AR25="R2",1,0))} -> 0
A26: PTE HAO QIAN | B26: =SUM(C26:D26) -> 4 | C26: =SUM(F26:AR26) -> 2 | D26: {=SUM(IF(F26:AR26="R",1,0))} -> 2 | E26: {=SUM(IF(F26:AR26="R2",1,0))} -> 2 | G26: r | R26: r | Z26: r2 | AD26: 1 | AK26: r2 | AQ26: 1
A27: PTE JIREH | B27: =SUM(C27:D27) -> 3 | C27: =SUM(F27:AR27) -> 2 | D27: {=SUM(IF(F27:AR27="R",1,0))} -> 1 | E27: {=SUM(IF(F27:AR27="R2",1,0))} -> 2 | G27: 1 | R27: 1 | AD27: r | AJ27: r2 | AO27: r2
A28: PTE IDHAR | C28: =SUM(F28:AR28) -> 2 | D28: {=SUM(IF(F28:AR28="R",1,0))} -> 2 | E28: {=SUM(IF(F28:AR28="R2",1,0))} -> 2 | H28: r | L28: r2 | N28: 1 | U28: r2 | AK28: 1 | AR28: r
A29: PTE OREDAIN | C29: =SUM(F29:AR29) -> 2 | D29: {=SUM(IF(F29:AR29="R",1,0))} -> 2 | E29: {=SUM(IF(F29:AR29="R2",1,0))} -> 1 | P29: r | T29: 1 | AK29: r | AQ29: r2 | AR29: 1
A30: Total | B30: =SUM(B4:B13) -> 24 | C30: =SUM(F30:AR30) -> 39 | F30: =SUM(F3:F29) -> 1 | G30: =SUM(G3:G29) -> 1 | H30: =SUM(H3:H29) -> 1 | I30: =SUM(I3:I29) -> 1 | J30: =SUM(J3:J29) -> 1 | K30: =SUM(K3:K29) -> 1 | L30: =SUM(L3:L29) -> 1 | M30: =SUM(M3:M29) -> 1 | ... AR30: =SUM(AR3:AR29) -> 1
A31: Reserve 1 | B31: =SUM(F31:AR31) -> 39 | C31: =SUM(F31:AR31) -> 39 | F31: {=SUM(IF(F3:F29="R",1,0))} -> 1 | G31: {=SUM(IF(G3:G29="R",1,0))} -> 1 | H31: {=SUM(IF(H3:H29="R",1,0))} -> 1 | I31: {=SUM(IF(I3:I29="R",1,0))} -> 1 | J31: {=SUM(IF(J3:J29="R",1,0))} -> 1 | K31: {=SUM(IF(K3:K29="R",1,0))} -> 1 | L31: {=SUM(IF(L3:L29="R",1,0))} -> 1 | M31: {=SUM(IF(M3:M29="R",1,0))} -> 1 | ... AR31: {=SUM(IF(AR3:AR29="R",1,0))} -> 1
A32: Reserve 2 | B32: =SUM(F32:AR32) -> 39 | C32: =SUM(F32:AR32) -> 39 | F32: {=SUM(IF(F3:F29="R2",1,0))} -> 1 | G32: {=SUM(IF(G3:G29="R2",1,0))} -> 1 | H32: {=SUM(IF(H3:H29="R2",1,0))} -> 1 | I32: {=SUM(IF(I3:I29="R2",1,0))} -> 1 | J32: {=SUM(IF(J3:J29="R2",1,0))} -> 1 | K32: {=SUM(IF(K3:K29="R2",1,0))} -> 1 | L32: {=SUM(IF(L3:L29="R2",1,0))} -> 1 | M32: {=SUM(IF(M3:M29="R2",1,0))} -> 1 | ... AR32: {=SUM(IF(AR3:AR29="R2",1,0))} -> 1
A33: Total Days | C33: =COUNTA(F1:AR1) -> 39 | E33: Duty Clerk | F33: =IFERROR(INDEX($A$3:$A$29, MATCH(1, INDEX($F$3:$AR$29, 0, MATCH(F2, $F$2:$AR$2, 0)), 0)), INDEX($A$3:$A$29, MATCH(1, INDEX($F$3:$AR$29, 0, MATCH(F2&" AM", $F$2:$AR$2, 0)), 0))) -> REC ASH | G33: =IFERROR(INDEX($A$3:$A$29, MATCH(1, INDEX($F$3:$AR$29, 0, MATCH(G2, $F$2:$AR$2, 0)), 0)), INDEX($A$3:$A$29, MATCH(1, INDEX($F$3:$AR$29, 0, MATCH(G2&" AM", $F$2:$AR$2, 0)), 0))) -> PTE JIREH | H33: =IFERROR(INDEX($A$3:$A$29, MATCH(1, INDEX($F$3:$AR$29, 0, MATCH(H2, $F$2:$AR$2, 0)), 0)), INDEX($A$3:$A$29, MATCH(1, INDEX($F$3:$AR$29, 0, MATCH(H2&" AM", $F$2:$AR$2, 0)), 0))) -> LCP AMIRUL | I33: =IFERROR(INDEX($A$3:$A$29, MATCH(1, INDEX($F$3:$AR$29, 0, MATCH(I2, $F$2:$AR$2, 0)), 0)), INDEX($A$3:$A$29, MATCH(1, INDEX($F$3:$AR$29, 0, MATCH(I2&" AM", $F$2:$AR$2, 0)), 0))) -> PTE HOI REI | J33: =IFERROR(INDEX($A$3:$A$29, MATCH(1, INDEX($F$3:$AR$29, 0, MATCH(J2, $F$2:$AR$2, 0)), 0)), INDEX($A$3:$A$29, MATCH(1, INDEX($F$3:$AR$29, 0, MATCH(J2&" AM", $F$2:$AR$2, 0)), 0))) -> PTE JASPER | K33: =IFERROR(INDEX($A$3:$A$29, MATCH(1, INDEX($F$3:$AR$29, 0, MATCH(K2, $F$2:$AR$2, 0)), 0)), INDEX($A$3:$A$29, MATCH(1, INDEX($F$3:$AR$29, 0, MATCH(K2&" AM", $F$2:$AR$2, 0)), 0))) -> PTE HAQIMI | L33: =IFERROR(INDEX($A$3:$A$29, MATCH(1, INDEX($F$3:$AR$29, 0, MATCH(L2, $F$2:$AR$2, 0)), 0)), INDEX($A$3:$A$29, MATCH(1, INDEX($F$3:$AR$29, 0, MATCH(L2&" AM", $F$2:$AR$2, 0)), 0))) -> PTE AMIN | M33: =IFERROR(INDEX($A$3:$A$29, MATCH(1, INDEX($F$3:$AR$29, 0, MATCH(M2, $F$2:$AR$2, 0)), 0)), INDEX($A$3:$A$29, MATCH(1, INDEX($F$3:$AR$29, 0, MATCH(M2&" AM", $F$2:$AR$2, 0)), 0))) -> REC PARAM | ... AR33: =IFERROR(INDEX($A$3:$A$29, MATCH(1, INDEX($F$3:$AR$29, 0, MATCH(AR2, $F$2:$AR$2, 0)), 0)), INDEX($A$3:$A$29, MATCH(1, INDEX($F$3:$AR$29, 0, MATCH(AR2&" AM", $F$2:$AR$2, 0)), 0))) -> PTE OREDAIN
A34: Total Personnel | C34: =SUBTOTAL(103, $A$3:$A$29) -> 23 | E34: Reserve | F34: =INDEX($A$3:$A$29, MATCH("R", INDEX($F$3:$AR$29, 0, MATCH(F2, $F$2:$AR$2, 0)), 0)) -> PTE JASPER | G34: =INDEX($A$3:$A$29, MATCH("R", INDEX($F$3:$AR$29, 0, MATCH(G2, $F$2:$AR$2, 0)), 0)) -> PTE HAO QIAN | H34: =INDEX($A$3:$A$29, MATCH("R", INDEX($F$3:$AR$29, 0, MATCH(H2, $F$2:$AR$2, 0)), 0)) -> PTE IDHAR | I34: =INDEX($A$3:$A$29, MATCH("R", INDEX($F$3:$AR$29, 0, MATCH(I2, $F$2:$AR$2, 0)), 0)) -> PTE ANGELO | J34: =INDEX($A$3:$A$29, MATCH("R", INDEX($F$3:$AR$29, 0, MATCH(J2, $F$2:$AR$2, 0)), 0)) -> SCT DANIEL | K34: =INDEX($A$3:$A$29, MATCH("R", INDEX($F$3:$AR$29, 0, MATCH(K2, $F$2:$AR$2, 0)), 0)) -> PTE AMIN | L34: =INDEX($A$3:$A$29, MATCH("R", INDEX($F$3:$AR$29, 0, MATCH(L2, $F$2:$AR$2, 0)), 0)) -> PTE EZRA | M34: =INDEX($A$3:$A$29, MATCH("R", INDEX($F$3:$AR$29, 0, MATCH(M2, $F$2:$AR$2, 0)), 0)) -> PTE RIFQI | ... AR34: =INDEX($A$3:$A$29, MATCH("R", INDEX($F$3:$AR$29, 0, MATCH(AR2, $F$2:$AR$2, 0)), 0)) -> PTE IDHAR
E35: Reserve 2 | F35: =INDEX($A$3:$A$29, MATCH("R2", INDEX($F$3:$AR$29, 0, MATCH(F2, $F$2:$AR$2, 0)), 0)) -> REC RUI FENG | G35: =INDEX($A$3:$A$29, MATCH("R2", INDEX($F$3:$AR$29, 0, MATCH(G2, $F$2:$AR$2, 0)), 0)) -> SCT DANIEL | H35: =INDEX($A$3:$A$29, MATCH("R2", INDEX($F$3:$AR$29, 0, MATCH(H2, $F$2:$AR$2, 0)), 0)) -> LCP ERNEST | I35: =INDEX($A$3:$A$29, MATCH("R2", INDEX($F$3:$AR$29, 0, MATCH(I2, $F$2:$AR$2, 0)), 0)) -> LCP ADAM | J35: =INDEX($A$3:$A$29, MATCH("R2", INDEX($F$3:$AR$29, 0, MATCH(J2, $F$2:$AR$2, 0)), 0)) -> PTE AMIN | K35: =INDEX($A$3:$A$29, MATCH("R2", INDEX($F$3:$AR$29, 0, MATCH(K2, $F$2:$AR$2, 0)), 0)) -> PTE JASPER | L35: =INDEX($A$3:$A$29, MATCH("R2", INDEX($F$3:$AR$29, 0, MATCH(L2, $F$2:$AR$2, 0)), 0)) -> PTE IDHAR | M35: =INDEX($A$3:$A$29, MATCH("R2", INDEX($F$3:$AR$29, 0, MATCH(M2, $F$2:$AR$2, 0)), 0)) -> PTE JASPER | ... AR35: =INDEX($A$3:$A$29, MATCH("R2", INDEX($F$3:$AR$29, 0, MATCH(AR2, $F$2:$AR$2, 0)), 0)) -> PTE HOI REI
A39: Excuse Stay in
A40: PA
A41: R&D
A42: RM
A43: PR
...

Sheet October Master Duty Overview
A1: Duty Personnel Duty | B1: Total Points | C1: Duty Points | D1: Reserve Points | E1: Reserve Points 2 | F1: TUESDAY | G1: WEDNESDAY | H1: THURSDAY | I1: FRIDAY | J1: SATURDAY (AM) | K1: SATURDAY (PM) | L1: SUNDAY (AM) | M1: SUNDAY (PM) | N1: MONDAY | O1: TUESDAY | P1: WEDNESDAY | Q1: THURSDAY | R1: FRIDAY | S1: SATURDAY (AM) | T1: SATURDAY (PM) | U1: SUNDAY (AM) | V1: SUNDAY (PM) | W1: MONDAY | X1: TUESDAY | Y1: WEDNESDAY | Z1: THURSDAY | AA1: FRIDAY | AB1: SATURDAY (AM) | AC1: SATURDAY (PM) | AD1: SUNDAY (AM) | AE1: SUNDAY (PM) | AF1: MONDAY | AG1: TUESDAY | AH1: WEDNESDAY | AI1: THURSDAY | AJ1: FRIDAY | AK1: SATURDAY (AM) | AL1: SATURDAY (PM) | AM1: SUNDAY (AM) | AN1: SUNDAY (PM) | AO1: MONDAY | AP1: TUESDAY | AQ1: WEDNESDAY | AR1: THURSDAY (AM) | AS1: THURSDAY (PM)
F2: 45566 | G2: 45567 | H2: 45568 | I2: 45569 | J2: 5-10-24 (AM) | K2: 5-10-24 (PM) | L2: 6-10-24 (AM) | M2: 6-10-24 (PM) | N2: 45572 | O2: 45573 | P2: 45574 | Q2: 45575 | R2: 45576 | S2: 12-10-24 (AM) | T2: 12-10-24 (PM) | U2: 13-10-24 (AM) | V2: 13-10-24 (PM) | W2: 45579 | X2: 45580 | Y2: 45581 | Z2: 45582 | AA2: 45583 | AB2: 19-10-24 (AM) | AC2: 19-10-24 (PM) | AD2: 20-10-24 (AM) | AE2: 20-10-24 (PM) | AF2: 45586 | AG2: 45587 | AH2: 45588 | AI2: 45589 | AJ2: 45590 | AK2: 26-10-24 (AM) | AL2: 26-10-24 (PM) | AM2: 27-10-24 (AM) | AN2: 27-10-24 (PM) | AO2: 45593 | AP2: 45594 | AQ2: 45595 | AR2: 31-10-24 (PAM) | AS2: 31-10-24 (PPM)
A3: PTE EZRA | B3: =SUM(C3:D3) -> 3 | C3: =SUM(F3:AS3) -> 2 | D3: {=SUM(IF(F3:AS3="R",1,0))} -> 1 | E3: {=SUM(IF(F3:AS3="R2",1,0))} -> 1 | L3: R2 | W3: r | AC3: 1 | AR3: 1
A4: LCP ERNEST | B4: =SUM(C4:D4) -> 4 | C4: =SUM(F4:AS4) -> 2 | D4: {=SUM(IF(F4:AS4="R",1,0))} -> 2 | E4: {=SUM(IF(F4:AS4="R2",1,0))} -> 1 | M4: 1 | R4: r2 | AE4: r | AG4: r | AP4: 1
A5: LCP FIRMAN | B5: =SUM(C5:D5) -> 3 | C5: =SUM(F5:AS5) -> 2 | D5: {=SUM(IF(F5:AS5="R",1,0))} -> 1 | E5: {=SUM(IF(F5:AS5="R2",1,0))} -> 2 | T5: 1 | V5: r2 | AM5: 1 | AN5: r2 | AP5: r
A6: PTE AFIF | B6: =SUM(C6:D6) -> 4 | C6: =SUM(F6:AS6) -> 2 | D6: {=SUM(IF(F6:AS6="R",1,0))} -> 2 | E6: {=SUM(IF(F6:AS6="R2",1,0))} -> 2 | AD6: 1 | AM6: r2 | AN6: 1 | AP6: r2 | AQ6: r | AS6: r
A7: PTE DYLAN | C7: =SUM(F7:AS7) -> 1 | D7: {=SUM(IF(F7:AS7="R",1,0))} -> 1 | E7: {=SUM(IF(F7:AS7="R2",1,0))} -> 1 | AD7: R | AQ7: 1 | AR7: r2
A8: PTE AZHARI | C8: =SUM(F8:AS8) -> 1 | D8: {=SUM(IF(F8:AS8="R",1,0))} -> 2 | E8: {=SUM(IF(F8:AS8="R2",1,0))} -> 2 | U8: r | W8: r2 | AE8: 1 | AK8: r2 | AO8: R
A9: LCP ADAM | B9: =SUM(C9:D9) -> 3 | C9: =SUM(F9:AS9) -> 1 | D9: {=SUM(IF(F9:AS9="R",1,0))} -> 2 | E9: {=SUM(IF(F9:AS9="R2",1,0))} -> 2 | F9: r2 | AG9: r2 | AL9: r | AN9: r | AS9: 1
A10: LCP AMIRUL | B10: =SUM(C10:D10) -> 6 | C10: =SUM(F10:AS10) -> 4 | D10: {=SUM(IF(F10:AS10="R",1,0))} -> 2 | E10: {=SUM(IF(F10:AS10="R2",1,0))} -> 2 | F10: 1 | J10: 1 | P10: r | R10: r | AC10: r2 | AF10: 1 | AL10: 1 | AO10: r2
A11: REC RUI FENG | B11: =SUM(C11:D11) -> 4 | C11: =SUM(F11:AS11) -> 2 | D11: {=SUM(IF(F11:AS11="R",1,0))} -> 2 | E11: {=SUM(IF(F11:AS11="R2",1,0))} -> 1 | L11: 1 | U11: 1 | AB11: r | AD11: r2 | AK11: r
A12: 3SG DANIEL | B12: =SUM(C12:D12) -> 3 | C12: =SUM(F12:AS12) -> 2 | D12: {=SUM(IF(F12:AS12="R",1,0))} -> 1 | E12: {=SUM(IF(F12:AS12="R2",1,0))} -> 2 | I12: 1 | P12: r2 | X12: r | Y12: r2 | AB12: 1
A13: PTE ANGELO | B13: =SUM(C13:D13) -> 3 | C13: =SUM(F13:AS13) -> 1 | D13: {=SUM(IF(F13:AS13="R",1,0))} -> 2 | E13: {=SUM(IF(F13:AS13="R2",1,0))} -> 1 | T13: r2 | X13: 1 | AM13: r | AR13: r
A14: REC ETHAN | B14: =SUM(C14:D14) -> 0 | C14: =SUM(F14:AS14) -> 0 | D14: {=SUM(IF(F14:AS14="R",1,0))} -> 0 | E14: {=SUM(IF(F14:AS14="R2",1,0))} -> 0
A15: PTE AMIN | C15: =SUM(F15:AS15) -> 2 | D15: {=SUM(IF(F15:AS15="R",1,0))} -> 2 | E15: {=SUM(IF(F15:AS15="R2",1,0))} -> 2 | J15: r | K15: r2 | N15: 1 | R15: 1 | AF15: r2 | AH15: r
A16: PTE JASPER | B16: =SUM(C16:D16) -> 4 | C16: =SUM(F16:AS16) -> 2 | D16: {=SUM(IF(F16:AS16="R",1,0))} -> 2 | E16: {=SUM(IF(F16:AS16="R2",1,0))} -> 2 | J16: r2 | K16: 1 | N16: r | Y16: r | Z16: 1 | AE16: r2
A17: PTE ISAAC | C17: =SUM(F17:AS17) -> 2 | D17: {=SUM(IF(F17:AS17="R",1,0))} -> 2 | E17: {=SUM(IF(F17:AS17="R2",1,0))} -> 2 | K17: r | Y17: 1 | Z17: r2 | AC17: r | AH17: 1 | AQ17: r2
A18: REC PARAM | C18: =SUM(F18:AS18) -> 2 | D18: {=SUM(IF(F18:AS18="R",1,0))} -> 1 | E18: {=SUM(IF(F18:AS18="R2",1,0))} -> 2 | L18: R | S18: 1 | U18: r2 | AB18: r2 | AK18: 1
A19: PTE RIFQI | B19: =SUM(C19:D19) -> 0 | C19: =SUM(F19:AS19) -> 0 | D19: {=SUM(IF(F19:AS19="R",1,0))} -> 0 | E19: {=SUM(IF(F19:AS19="R2",1,0))} -> 0
A20: REC ASH | C20: =SUM(F20:AS20) -> 2 | D20: {=SUM(IF(F20:AS20="R",1,0))} -> 1 | E20: {=SUM(IF(F20:AS20="R2",1,0))} -> 1 | G20: 1 | O20: r2 | AA20: 1 | AI20: r
A21: PTE HAQIMI | B21: =SUM(C21:D21) -> 3 | C21: =SUM(F21:AS21) -> 2 | D21: {=SUM(IF(F21:AS21="R",1,0))} -> 1 | E21: {=SUM(IF(F21:AS21="R2",1,0))} -> 1 | O21: r | Q21: 1 | AI21: r2 | AJ21: 1
A22: PTE DARREN | B22: =SUM(C22:D22) -> 3 | C22: =SUM(F22:AS22) -> 1 | D22: {=SUM(IF(F22:AS22="R",1,0))} -> 2 | E22: {=SUM(IF(F22:AS22="R2",1,0))} -> 2 | H22: r | M22: r | N22: r2 | AA22: r2 | AG22: 1
A23: PTE SAMEER | B23: =SUM(C23:D23) -> 3 | C23: =SUM(F23:AS23) -> 0 | D23: {=SUM(IF(F23:AS23="R",1,0))} -> 3 | E23: {=SUM(IF(F23:AS23="R2",1,0))} -> 3 | G23: r | H23: r2 | X23: r2 | Z23: r | AF23: r | AS23: r2
A24: PTE XIAO YU | B24: =SUM(C24:D24) -> 2 | C24: =SUM(F24:AS24) -> 1 | D24: {=SUM(IF(F24:AS24="R",1,0))} -> 1 | E24: {=SUM(IF(F24:AS24="R2",1,0))} -> 1 | M24: r2 | V24: r | AI24: 1
A25: SCT YUSUF | C25: =SUM(F25:AS25) -> 0 | D25: {=SUM(IF(F25:AS25="R",1,0))} -> 0 | E25: {=SUM(IF(F25:AS25="R2",1,0))} -> 0
A26: PTE HOI REI | C26: =SUM(F26:AS26) -> 1 | D26: {=SUM(IF(F26:AS26="R",1,0))} -> 2 | E26: {=SUM(IF(F26:AS26="R2",1,0))} -> 2 | O26: 1 | Q26: r2 | S26: r | AA26: r | AL26: r2
A27: PTE REUVEN | B27: =SUM(C27:D27) -> 0 | C27: =SUM(F27:AS27) -> 0 | D27: {=SUM(IF(F27:AS27="R",1,0))} -> 0 | E27: {=SUM(IF(F27:AS27="R2",1,0))} -> 0
A28: PTE HAO QIAN | B28: =SUM(C28:D28) -> 2 | C28: =SUM(F28:AS28) -> 1 | D28: {=SUM(IF(F28:AS28="R",1,0))} -> 1 | E28: {=SUM(IF(F28:AS28="R2",1,0))} -> 1 | H28: 1 | I28: r | S28: r2
A29: PTE JIREH | B29: =SUM(C29:D29) -> 4 | C29: =SUM(F29:AS29) -> 2 | D29: {=SUM(IF(F29:AS29="R",1,0))} -> 2 | E29: {=SUM(IF(F29:AS29="R2",1,0))} -> 2 | F29: r | G29: r2 | P29: 1 | T29: r | V29: 1 | AJ29: r2
A30: PTE MICHAEL | C30: =SUM(F30:AS30) -> 2 | D30: {=SUM(IF(F30:AS30="R",1,0))} -> 2 | E30: {=SUM(IF(F30:AS30="R2",1,0))} -> 2 | I30: r2 | Q30: r | W30: 1 | AH30: r2 | AJ30: r | AO30: 1
A31: Total | B31: =SUM(B4:B14) -> 30 | C31: =SUM(F31:AS31) -> 40 | F31: =SUM(F3:F30) -> 1 | G31: =SUM(G3:G30) -> 1 | H31: =SUM(H3:H30) -> 1 | I31: =SUM(I3:I30) -> 1 | J31: =SUM(J3:J30) -> 1 | K31: =SUM(K3:K30) -> 1 | L31: =SUM(L3:L30) -> 1 | M31: =SUM(M3:M30) -> 1 | ... AS31: =SUM(AS3:AS30) -> 1
A32: Reserve 1 | B32: =SUM(F32:AR32) -> 39 | C32: =SUM(F32:AS32) -> 40 | F32: {=SUM(IF(F3:F30="R",1,0))} -> 1 | G32: {=SUM(IF(G3:G30="R",1,0))} -> 1 | H32: {=SUM(IF(H3:H30="R",1,0))} -> 1 | I32: {=SUM(IF(I3:I30="R",1,0))} -> 1 | J32: {=SUM(IF(J3:J30="R",1,0))} -> 1 | K32: {=SUM(IF(K3:K30="R",1,0))} -> 1 | L32: {=SUM(IF(L3:L30="R",1,0))} -> 1 | M32: {=SUM(IF(M3:M30="R",1,0))} -> 1 | ... AS32: {=SUM(IF(AS3:AS30="R",1,0))} -> 1
A33: Reserve 2 | B33: =SUM(F33:AR33) -> 39 | C33: =SUM(F33:AS33) -> 40 | F33: {=SUM(IF(F3:F30="R2",1,0))} -> 1 | G33: {=SUM(IF(G3:G30="R2",1,0))} -> 1 | H33: {=SUM(IF(H3:H30="R2",1,0))} -> 1 | I33: {=SUM(IF(I3:I30="R2",1,0))} -> 1 | J33: {=SUM(IF(J3:J30="R2",1,0))} -> 1 | K33: {=SUM(IF(K3:K30="R2",1,0))} -> 1 | L33: {=SUM(IF(L3:L30="R2",1,0))} -> 1 | M33: {=SUM(IF(M3:M30="R2",1,0))} -> 1 | ... AS33: {=SUM(IF(AS3:AS30="R2",1,0))} -> 1
E34: Duty Clerk | F34: =IFERROR(INDEX($A$3:$A$30, MATCH(1, INDEX($F$3:$AR$30, 0, MATCH(F2, $F$2:$AR$2, 0)), 0)), INDEX($A$3:$A$30, MATCH(1, INDEX($F$3:$AR$30, 0, MATCH(F2&" AM", $F$2:$AR$2, 0)), 0))) -> LCP AMIRUL | G34: =IFERROR(INDEX($A$3:$A$30, MATCH(1, INDEX($F$3:$AR$30, 0, MATCH(G2, $F$2:$AR$2, 0)), 0)), INDEX($A$3:$A$30, MATCH(1, INDEX($F$3:$AR$30, 0, MATCH(G2&" AM", $F$2:$AR$2, 0)), 0))) -> REC ASH | H34: =IFERROR(INDEX($A$3:$A$30, MATCH(1, INDEX($F$3:$AR$30, 0, MATCH(H2, $F$2:$AR$2, 0)), 0)), INDEX($A$3:$A$30, MATCH(1, INDEX($F$3:$AR$30, 0, MATCH(H2&" AM", $F$2:$AR$2, 0)), 0))) -> PTE HAO QIAN | I34: =IFERROR(INDEX($A$3:$A$30, MATCH(1, INDEX($F$3:$AR$30, 0, MATCH(I2, $F$2:$AR$2, 0)), 0)), INDEX($A$3:$A$30, MATCH(1, INDEX($F$3:$AR$30, 0, MATCH(I2&" AM", $F$2:$AR$2, 0)), 0))) -> 3SG DANIEL | J34: =IFERROR(INDEX($A$3:$A$30, MATCH(1, INDEX($F$3:$AR$30, 0, MATCH(J2, $F$2:$AR$2, 0)), 0)), INDEX($A$3:$A$30, MATCH(1, INDEX($F$3:$AR$30, 0, MATCH(J2&" AM", $F$2:$AR$2, 0)), 0))) -> LCP AMIRUL | K34: =IFERROR(INDEX($A$3:$A$30, MATCH(1, INDEX($F$3:$AR$30, 0, MATCH(K2, $F$2:$AR$2, 0)), 0)), INDEX($A$3:$A$30, MATCH(1, INDEX($F$3:$AR$30, 0, MATCH(K2&" AM", $F$2:$AR$2, 0)), 0))) -> PTE JASPER | L34: =IFERROR(INDEX($A$3:$A$30, MATCH(1, INDEX($F$3:$AR$30, 0, MATCH(L2, $F$2:$AR$2, 0)), 0)), INDEX($A$3:$A$30, MATCH(1, INDEX($F$3:$AR$30, 0, MATCH(L2&" AM", $F$2:$AR$2, 0)), 0))) -> REC RUI FENG | M34: =IFERROR(INDEX($A$3:$A$30, MATCH(1, INDEX($F$3:$AR$30, 0, MATCH(M2, $F$2:$AR$2, 0)), 0)), INDEX($A$3:$A$30, MATCH(1, INDEX($F$3:$AR$30, 0, MATCH(M2&" AM", $F$2:$AR$2, 0)), 0))) -> LCP ERNEST | ... AR34: =IFERROR(INDEX($A$3:$A$30, MATCH(1, INDEX($F$3:$AR$30, 0, MATCH(AR2, $F$2:$AR$2, 0)), 0)), INDEX($A$3:$A$30, MATCH(1, INDEX($F$3:$AR$30, 0, MATCH(AR2&" AM", $F$2:$AR$2, 0)), 0))) -> PTE EZRA | AS34: {=IFERROR(INDEX($A$3:$A$30, MATCH(1, INDEX($F$3:$AS$30, 0, MATCH(AS2, $F$2:$AS$2, 0)), 0)), INDEX($A$3:$A$30, MATCH(1, INDEX($F$3:$AS$30, 0, MATCH(AS2&" AM", $F$2:$AS$2, 0)), 0)))} -> LCP ADAM
A35: Total Days | C35: =COUNTA($F$1:$AS$1) -> 40 | E35: Reserve | F35: =INDEX($A$3:$A$30, MATCH("R", INDEX($F$3:$AS$30, 0, MATCH(F2, $F$2:$AS$2, 0)), 0)) -> PTE JIREH | G35: =INDEX($A$3:$A$30, MATCH("R", INDEX($F$3:$AS$30, 0, MATCH(G2, $F$2:$AS$2, 0)), 0)) -> PTE SAMEER | H35: =INDEX($A$3:$A$30, MATCH("R", INDEX($F$3:$AS$30, 0, MATCH(H2, $F$2:$AS$2, 0)), 0)) -> PTE DARREN | I35: =INDEX($A$3:$A$30, MATCH("R", INDEX($F$3:$AS$30, 0, MATCH(I2, $F$2:$AS$2, 0)), 0)) -> PTE HAO QIAN | J35: =INDEX($A$3:$A$30, MATCH("R", INDEX($F$3:$AS$30, 0, MATCH(J2, $F$2:$AS$2, 0)), 0)) -> PTE AMIN | K35: =INDEX($A$3:$A$30, MATCH("R", INDEX($F$3:$AS$30, 0, MATCH(K2, $F$2:$AS$2, 0)), 0)) -> PTE ISAAC | L35: =INDEX($A$3:$A$30, MATCH("R", INDEX($F$3:$AS$30, 0, MATCH(L2, $F$2:$AS$2, 0)), 0)) -> REC PARAM | M35: =INDEX($A$3:$A$30, MATCH("R", INDEX($F$3:$AS$30, 0, MATCH(M2, $F$2:$AS$2, 0)), 0)) -> PTE DARREN | ... AS35: =INDEX($A$3:$A$30, MATCH("R", INDEX($F$3:$AS$30, 0, MATCH(AS2, $F$2:$AS$2, 0)), 0)) -> PTE AFIF
A36: Total Personnel | C36: =SUBTOTAL(103, $A$3:$A$30) -> 24 | E36: Reserve 2 | F36: =INDEX($A$3:$A$30, MATCH("R2", INDEX($F$3:$AS$30, 0, MATCH(F2, $F$2:$AS$2, 0)), 0)) -> LCP ADAM | G36: =INDEX($A$3:$A$30, MATCH("R2", INDEX($F$3:$AS$30, 0, MATCH(G2, $F$2:$AS$2, 0)), 0)) -> PTE JIREH | H36: =INDEX($A$3:$A$30, MATCH("R2", INDEX($F$3:$AS$30, 0, MATCH(H2, $F$2:$AS$2, 0)), 0)) -> PTE SAMEER | I36: =INDEX($A$3:$A$30, MATCH("R2", INDEX($F$3:$AS$30, 0, MATCH(I2, $F$2:$AS$2, 0)), 0)) -> PTE MICHAEL | J36: =INDEX($A$3:$A$30, MATCH("R2", INDEX($F$3:$AS$30, 0, MATCH(J2, $F$2:$AS$2, 0)), 0)) -> PTE JASPER | K36: =INDEX($A$3:$A$30, MATCH("R2", INDEX($F$3:$AS$30, 0, MATCH(K2, $F$2:$AS$2, 0)), 0)) -> PTE AMIN | L36: =INDEX($A$3:$A$30, MATCH("R2", INDEX($F$3:$AS$30, 0, MATCH(L2, $F$2:$AS$2, 0)), 0)) -> PTE EZRA | M36: =INDEX($A$3:$A$30, MATCH("R2", INDEX($F$3:$AS$30, 0, MATCH(M2, $F$2:$AS$2, 0)), 0)) -> PTE XIAO YU | ... AS36: =INDEX($A$3:$A$30, MATCH("R2", INDEX($F$3:$AS$30, 0, MATCH(AS2, $F$2:$AS$2, 0)), 0)) -> PTE SAMEER
A40: Excuse Stay in
A41: PA
A42: R&D
A43: RM
...

Sheet November Master Duty Overview
A1: Duty Personnel Duty | B1: Total Points | C1: Duty Points | D1: Reserve Points | E1: Reserve Points 2 | F1: FRIDAY | G1: SATURDAY (AM) | H1: SATURDAY (PM) | I1: SUNDAY (AM) | J1: SUNDAY (PM) | K1: MONDAY | L1: TUESDAY | M1: WEDNESDAY | N1: THURSDAY | O1: FRIDAY | P1: SATURDAY (AM) | Q1: SATURDAY (PM) | R1: SUNDAY (AM) | S1: SUNDAY (PM) | T1: MONDAY | U1: TUESDAY | V1: WEDNESDAY | W1: THURSDAY | X1: FRIDAY | Y1: SATURDAY (AM) | Z1: SATURDAY (PM) | AA1: SUNDAY (AM) | AB1: SUNDAY (PM) | AC1: MONDAY | AD1: TUESDAY | AE1: WEDNESDAY | AF1: THURSDAY | AG1: FRIDAY | AH1: SATURDAY (AM) | AI1: SATURDAY (PM) | AJ1: SUNDAY (AM) | AK1: SUNDAY (PM) | AL1: MONDAY | AM1: TUESDAY | AN1: WEDNESDAY | AO1: THURSDAY | AP1: FRIDAY | AQ1: SATURDAY (AM) | AR1: SATURDAY (PM) | AS1: SUNDAY (AM) | AT1: SUNDAY (PM)
F2: 45597 | G2: 2-11-24 (AM) | H2: 2-11-24 (PM) | I2: 3-11-24 (AM) | J2: 3-11-24 (PM) | K2: 45600 | L2: 45601 | M2: 45602 | N2: 45603 | O2: 45604 | P2: 9-11-24 (AM) | Q2: 9-11-24 (PM) | R2: 10-11-24 (AM) | S2: 10-11-24 (PM) | T2: 45607 | U2: 45608 | V2: 45609 | W2: 45610 | X2: 45611 | Y2: 16-11-24 (AM) | Z2: 16-11-24 (PM) | AA2: 17-11-24 (AM) | AB2: 17-11-24 (PM) | AC2: 45614 | AD2: 45615 | AE2: 45616 | AF2: 45617 | AG2: 45618 | AH2: 23-11-24 (AM) | AI2: 23-11-24 (PM) | AJ2: 24-11-24 (AM) | AK2: 24-11-24 (PM) | AL2: 45621 | AM2: 45622 | AN2: 45623 | AO2: 45624 | AP2: 45625 | AQ2: 30-11-24 (AM) | AR2: 30-11-24 (PM) | AS2: 13-10-24 (AM) | AT2: 13-10-24 (PM)
A3: PTE EZRA | B3: =SUM(C3:D3) -> 3 | C3: =SUM(F3:AS3) -> 2 | D3: {=SUM(IF(F3:AS3="R",1,0))} -> 1 | E3: {=SUM(IF(F3:AS3="R2",1,0))} -> 2 | F3: r2 | O3: r2 | Q3: 1 | AI3: 1 | AP3: r
A4: LCP ERNEST | B4: =SUM(C4:D4) -> 0 | C4: =SUM(F4:AS4) -> 0 | D4: {=SUM(IF(F4:AS4="R",1,0))} -> 0 | E4: {=SUM(IF(F4:AS4="R2",1,0))} -> 0
A5: LCP FIRMAN | B5: =SUM(C5:D5) -> 3 | C5: =SUM(F5:AS5) -> 1 | D5: {=SUM(IF(F5:AS5="R",1,0))} -> 2 | E5: {=SUM(IF(F5:AS5="R2",1,0))} -> 1 | G5: r | H5: 1 | AC5: r | AF5: r2
A6: PTE AFIF | B6: =SUM(C6:D6) -> 3 | C6: =SUM(F6:AS6) -> 1 | D6: {=SUM(IF(F6:AS6="R",1,0))} -> 2 | E6: {=SUM(IF(F6:AS6="R2",1,0))} -> 1 | F6: r | AB6: r2 | AF6: r | AH6: 1
A7: PTE DYLAN | C7: =SUM(F7:AS7) -> 2 | D7: {=SUM(IF(F7:AS7="R",1,0))} -> 2 | E7: {=SUM(IF(F7:AS7="R2",1,0))} -> 2 | F7: 1 | N7: r2 | P7: r | U7: r | AA7: r2 | AF7: 1
